Workbook

Sheet Leitura
A1: Expurgos de transformadores — janeiro a agosto de 2026
A2: Como a base foi montada, o que cada termo significa e onde estão as dinâmicas.
A4: 1. Como a base foi extraída
A5: Código operativo | B5: Somente os que começam com 42, 52, 53 ou 57 — a faixa de transformador de distribuição.
A6: Status da SS | B6: Pendente e Atendida.
A7: Esquema de serviço | B7: MC - Substituição de transformador.
A8: Tipo de SS | B8: FORMS, AVISO DE ANOMALIA e SOLICITAÇÃO DE SERVIÇO.
A9: Período | B9: Aberturas de janeiro a agosto de 2026.
A10: Resultado | B10: Deste recorte saíram 227 solicitações expurgadas, que são as linhas da aba Expurgos.
A12: 2. O que é expurgo
A13: Definição | B13: SS que saiu do indicador de transformadores queimados. Cada linha traz o motivo, a categoria apurada na leitura caso a caso e o texto integral da SS e da OS.
A14: Dois grupos | B14: 115 saíram por mérito próprio e estão encerrados. 112 saíram porque a interrupção não fecha na Crítica e dependem de resposta do COPO — podem voltar ao indicador.
A16: 3. Glossário dos termos usados
A17: Sem interrupção registrada | B17: A Crítica não tem nenhuma interrupção neste transformador em data alguma do período.
A18: Fora da janela de 24 h | B18: A interrupção existe na Crítica, mas não cai na janela de 24 horas em torno da SS.
A19: Troca comprovada pela série | B19: O número de série do transformador retirado é diferente do instalado — a substituição de fato ocorreu.
A20: Obra não comprova a troca | B20: A obra, onde o material trocado é registrado, não foi gerada, não executou nada, ou foi encerrada sem transformador no material.
A21: Trocado, mas sem falha | B21: A troca ocorreu e está documentada, mas por decisão de capacidade ou de rede: remanejamento, preventivo, ajuste de tensão.
A22: Não houve troca nenhuma | B22: O registro diz que nada foi substituído: SS de construção, desativação de posto, ou segunda SS do mesmo evento.
A23: Causa externa ao transformador | B23: A reposição não foi por defeito do equipamento: furto, colisão, terceiros, ou o código nem é de transformador de distribuição.
A25: 4. Onde estão as dinâmicas
A26: Din Categoria | B26: Contagem por macro categoria — as cinco famílias de expurgo.
A27: Din Motivo | B27: Macro categoria aberta por motivo — os 19 motivos registrados.
A28: Din Texto x Motivo | B28: Categoria pelo texto da SS aberta por motivo — a visão dos 172 com texto de queima ou avaria.
A29: Planilha1 | B29: As duas dinâmicas que já vinham na base, preservadas como estavam.
A30: Atualizar | B30: As dinâmicas são atualizadas ao abrir. Para forçar: clique com o botão direito sobre a tabela e escolha Atualizar.
A32: 5. Ressalvas
A33: Julho | B33: A Crítica de julho se perdeu. Os 13 expurgos do mês foram lidos só pelo texto, sem conferência de interrupção — o mês não é comparável aos demais.
A34: Fonte da categoria | B34: 191 categorias vieram prontas da esteira das 1.582; 36 foram lidas caso a caso no período de janeiro a agosto.

Sheet Resumo
A1: Resumo dos 227 expurgos
A2: Todos os números saem por fórmula da aba Expurgos — mudou a base, muda aqui.
A3: Visão geral
A4: Situação | B4: SS | C4: %
A5: Com decisão fechada — não retornam ao indicador | B5: =227-B6 | C5: =B5/$B$7
A6: Aguardando o COPO — interrupção não fecha na Crítica | B6: =COUNTIFS(Expurgos!$D$2:$D$228,"Sem interrupção")+COUNTIFS(Expurgos!$D$2:$D$228,"Fora da janela") | C6: =B6/$B$7
A7: Total | B7: =COUNTA(Expurgos!$A$2:$A$228) | C7: =B7/B7
A9: Por macro categoria
A10: Macro categoria | B10: SS | C10: %
A11: Sem interrupção ou fora da janela | B11: =COUNTIFS(Expurgos!$C$2:$C$228,"Sem interrupção comprovada") | C11: =B11/$B$16
A12: Causa externa ao transformador | B12: =COUNTIFS(Expurgos!$C$2:$C$228,"Causa externa ao transformador") | C12: =B12/$B$16
A13: Trocado, mas sem falha | B13: =COUNTIFS(Expurgos!$C$2:$C$228,"Troca sem falha") | C13: =B13/$B$16
A14: Obra não comprova a troca | B14: =COUNTIFS(Expurgos!$C$2:$C$228,"Sem documento") | C14: =B14/$B$16
A15: Não houve troca nenhuma | B15: =COUNTIFS(Expurgos!$C$2:$C$228,"Não houve troca") | C15: =B15/$B$16
A16: Total | B16: =SUM(B11:B15) | C16: =B16/B16
A18: Os 172 com texto de queima ou avaria
A19: Recorte | B19: SS | C19: %
A20: Param na Crítica: sem interrupção ou fora da janela | B20: =(COUNTIFS(Expurgos!$F$2:$F$228,"QUEIMADO",Expurgos!$D$2:$D$228,"Sem interrupção")+COUNTIFS(Expurgos!$F$2:$F$228,"QUEIMADO",Expurgos!$D$2:$D$228,"Fora da janela")+COUNTIFS(Expurgos!$F$2:$F$228,"AVARIADO",Expurgos!$D$2:$D$228,"Sem interrupção")+COUNTIFS(Expurgos!$F$2:$F$228,"AVARIADO",Expurgos!$D$2:$D$228,"Fora da janela")) | C20: =B20/$B$22
A21: Saíram por motivo apurado na leitura | B21: =B22-B20 | C21: =B21/$B$22
A22: Total com texto de queima ou avaria | B22: =(COUNTIFS(Expurgos!$F$2:$F$228,"QUEIMADO")+COUNTIFS(Expurgos!$F$2:$F$228,"AVARIADO")) | C22: =B22/B22
A24: Por mês
A25: Mês | B25: Expurgos no mês | C25: Aguardando o COPO | D25: % do mês
A26: jan | B26: =COUNTIFS(Expurgos!$B$2:$B$228,"jan") | C26: =COUNTIFS(Expurgos!$B$2:$B$228,"jan",Expurgos!$D$2:$D$228,"Sem interrupção")+COUNTIFS(Expurgos!$B$2:$B$228,"jan",Expurgos!$D$2:$D$228,"Fora da janela") | D26: =IF(B26=0,0,C26/B26)
A27: fev | B27: =COUNTIFS(Expurgos!$B$2:$B$228,"fev") | C27: =COUNTIFS(Expurgos!$B$2:$B$228,"fev",Expurgos!$D$2:$D$228,"Sem interrupção")+COUNTIFS(Expurgos!$B$2:$B$228,"fev",Expurgos!$D$2:$D$228,"Fora da janela") | D27: =IF(B27=0,0,C27/B27)
A28: mar | B28: =COUNTIFS(Expurgos!$B$2:$B$228,"mar") | C28: =COUNTIFS(Expurgos!$B$2:$B$228,"mar",Expurgos!$D$2:$D$228,"Sem interrupção")+COUNTIFS(Expurgos!$B$2:$B$228,"mar",Expurgos!$D$2:$D$228,"Fora da janela") | D28: =IF(B28=0,0,C28/B28)
A29: abr | B29: =COUNTIFS(Expurgos!$B$2:$B$228,"abr") | C29: =COUNTIFS(Expurgos!$B$2:$B$228,"abr",Expurgos!$D$2:$D$228,"Sem interrupção")+COUNTIFS(Expurgos!$B$2:$B$228,"abr",Expurgos!$D$2:$D$228,"Fora da janela") | D29: =IF(B29=0,0,C29/B29)
A30: mai | B30: =COUNTIFS(Expurgos!$B$2:$B$228,"mai") | C30: =COUNTIFS(Expurgos!$B$2:$B$228,"mai",Expurgos!$D$2:$D$228,"Sem interrupção")+COUNTIFS(Expurgos!$B$2:$B$228,"mai",Expurgos!$D$2:$D$228,"Fora da janela") | D30: =IF(B30=0,0,C30/B30)
A31: jun | B31: =COUNTIFS(Expurgos!$B$2:$B$228,"jun") | C31: =COUNTIFS(Expurgos!$B$2:$B$228,"jun",Expurgos!$D$2:$D$228,"Sem interrupção")+COUNTIFS(Expurgos!$B$2:$B$228,"jun",Expurgos!$D$2:$D$228,"Fora da janela") | D31: =IF(B31=0,0,C31/B31)
A32: jul | B32: =COUNTIFS(Expurgos!$B$2:$B$228,"jul") | C32: =COUNTIFS(Expurgos!$B$2:$B$228,"jul",Expurgos!$D$2:$D$228,"Sem interrupção")+COUNTIFS(Expurgos!$B$2:$B$228,"jul",Expurgos!$D$2:$D$228,"Fora da janela") | D32: =IF(B32=0,0,C32/B32)
A33: ago | B33: =COUNTIFS(Expurgos!$B$2:$B$228,"ago") | C33: =COUNTIFS(Expurgos!$B$2:$B$228,"ago",Expurgos!$D$2:$D$228,"Sem interrupção")+COUNTIFS(Expurgos!$B$2:$B$228,"ago",Expurgos!$D$2:$D$228,"Fora da janela") | D33: =IF(B33=0,0,C33/B33)
A34: Total | B34: =SUM(B26:B33) | C34: =SUM(C26:C33) | D34: =C34/B34
A35: Julho não é comparável: a Crítica do mês se perdeu e a conferência de interrupção não rodou.
A37: Prova de troca dentro dos 112 pendentes
A38: Situação | B38: SS | C38: %
A39: Troca comprovada pela série | B39: =COUNTIFS(Expurgos!$D$2:$D$228,"Sem interrupção",Expurgos!$U$2:$U$228,"sim")+COUNTIFS(Expurgos!$D$2:$D$228,"Fora da janela",Expurgos!$U$2:$U$228,"sim") | C39: =B39/$B$41
A40: Sem comprovação pela série | B40: =B41-B39 | C40: =B40/$B$41
A41: Total pendente | B41: =B6 | C41: =B41/B41

Sheet Din Categoria
A1: Dinâmica: Categoria
A2: Contagem de SS por macro categoria. Arraste outros campos na lista à direita para explorar.

Sheet Din Motivo
A1: Dinâmica: Motivo
A2: Macro categoria aberta por motivo registrado na leitura caso a caso.

Sheet Din Texto x Motivo
A1: Dinâmica: Texto x Motivo
A2: Categoria pelo texto da SS aberta por motivo — é aqui que se lê a visão dos 172 com texto de queima ou avaria.

Sheet Planilha1
A3: Rótulos de Linha | B3: Contagem de SS | D3: Rótulos de Linha | E3: Contagem de SS
A4: ABALROAMENTO | B4: 5 | D4: AVARIADO | E4: 47
A5: AVARIADO | B5: 47 | D5: Divisão de circuito | E5: 1
A6: CONSTRUCAO | B6: 1 | D6: Falta de fase | E6: 1
A7: DESATIVACAO | B7: 2 | D7: Fora da janela | E7: 5
A8: FURTADO | B8: 30 | D8: Furto | E8: 2
A9: OUTROS | B9: 3 | D9: Preventivo | E9: 3
A10: PREVENTIVO | B10: 9 | D10: Remanejamento | E10: 4
A11: QUEIMADO | B11: 125 | D11: Sem interrupção | E11: 18
A12: SEM OS | B12: 2 | D12: Sem obra | E12: 3
A13: SEM TEXTO | B13: 1 | D13: Sem troca | E13: 5
A14: SOBRECARGA | B14: 1 | D14: Tap / tensão | E14: 5
A15: TRAFO AUXILIAR | B15: 1 | D15: QUEIMADO | E15: 125
A16: Total Geral | B16: 227 | D16: Abalroamento | E16: 2
D17: Dano de terceiros | E17: 1
D18: Erro de cadastro | E18: 2
D19: Falta de fase | E19: 1
D20: Fora da janela | E20: 25
D21: Furto | E21: 4
D22: Melhoria de posto | E22: 1
D23: Obra sem execução | E23: 1
D24: Obra sem transformador | E24: 3
D25: Preventivo | E25: 5
D26: Remanejamento | E26: 8
D27: Sem interrupção | E27: 64
D28: Sem obra | E28: 3
... D33: Total Geral | E33: 172

Sheet Detalhes1
A1: Detalhes do Contagem de SS - Motivo: Sem interrupção, Categoria pelo texto: QUEIMADO
A3: SS | B3: Mês | C3: Macro categoria | D3: Motivo | E3: Resultado | F3: Categoria pelo texto | G3: Fonte da categoria | H3: Categoria da leitura | I3: Trafo | J3: OS | K3: Obra | L3: Abertura | M3: Término | N3: Tipo da SS | O3: Equipe | P3: Localidade | Q3: Origem da SS | R3: Defeito da SS | S3: NS retirado | T3: NS instalado | U3: Prova de troca | V3: Crítica — causa | W3: Crítica — subcausa | X3: TMAE — causa | Y3: TMAE — subcausa | Z3: No Infotrafo | AA3: Origem da leitura | AB3: Por que saiu | AC3: Texto da SS | AD3: Texto da OS
A4: ETO-RD-AR 01225/2026 | B4: ago | C4: Sem interrupção comprovada | D4: Sem interrupção | E4: EXPURGO | F4: QUEIMADO | G4: leitura do texto (jan–ago) | H4: AUSENTE DA CRÍTICA | I4: 5720186077 | J4: ENC-MPAR02 000052/2026 | K4: 612600770 | L4: 2026-08-08 12:30 | M4: 2026-08-09 01:52 | N4: FORMS SUBST DE TRANSFORMADOR | O4: ETO-RD-AR | P4: GOIATINS | Q4: QUEIMADO | R4: NÃO IDENTIFICADO | S4: 978259 | U4: não | Z4: SIM | AA4: Crítica + TMAE de agosto (novo) | AB4: SS de transformador e para-raio queimados em Goiatins e OS do executante com o quadro completo de retirado (ITB, série 978259, 2015) e instalado (ITAM, série C303245, 2026), o que prova a troca física. O defeito de execução foi lançado como sobrecarga, causa de queima. Trafo ausente da crítica, o que é apenas falta de registro de interrupção e não desmente a falha. | AC4: TRANSFORMADOR QUEIMADO, PARA RAIO QUEIMADO.ACESSO A CAMINHONETE | AD4: ETO-RD-AR 1225/2026 TR: 5720186077 TRAFO RETIRADO POTÊNCIA : 15KVA TENSÃO : 34,5KV Nº ENERGISA (CITD) : 0618142 Nº DE SÉRIE : 978259 MARCA : ITB DATA FABRICAÇÃO : 11/2015 IMPEDANCIA : 3,10 POS. TAP : 05 TRAFO INSTALADO POTÊNCIA : 15KVA TENSÃO : 34,5KV Nº ENERGISA (CITD) : 150865 Nº DE SÉRIE : C303245 MARCA : ITAM DATA FABRICAÇÃO : 13/02/2026 IMPEDANCIA : 3,17 POS. TAP : 03
A5: DOLP-RD-PA 00888/2026 | B5: ago | C5: Sem interrupção comprovada | D5: Sem interrupção | E5: EXPURGO | F5: QUEIMADO | G5: leitura do texto (jan–ago) | H5: AUSENTE DA CRÍTICA | I5: 5750729059 | J5: DLP-MPPA01 000293/2026 | L5: 2026-08-22 13:11 | M5: 2026-08-22 18:00 | N5: FORMS SUBST DE TRANSFORMADOR | O5: DOLP-RD-PA | P5: PALMAS | Q5: QUEIMADO | R5: NÃO IDENTIFICADO | S5: 00 | T5: 0 | U5: não | Z5: SIM | AA5: Crítica + TMAE de agosto (novo) | AB5: Trafo de 112,5 kVA queimado em Palmas com 83 clientes penalizados. O texto da OS e copia literal da SS mais a baixa de material e os dados do atendimento, sem relato do executante, e o formulario veio zerado; o caso esta ausente da critica, o que e falta de registro de interrupcao e nao evidencia de que a falha nao ocorreu. A SS foi atendida no mesmo dia por equipe de manutencao com consumo de material. | AC5: segue ss de 01 trafo de 112,500kva da rede de 13.800kv queimado para ser subistituido pela equipe de manutencão acesso livre clientes penaloizados 83 equipe que atendeu 100op04 cel, 63999345829/992270907 favor agilizar o atendimento devido a quantidade de clientes penalizados | AD5: MEDIDO_ 1. Baixado para consumo de material segue ss de 01 trafo de 112,500kva da rede de 13.800kv queimado para ser subistituido pela equipe de manutencão acesso livre clientes penaloizados 83 equipe que atendeu 100op04 cel, 63999345829/992270907 favor agilizar o atendimento devido a quantidade de clientes penalizados DADOS DO ATENDIMENTO: EQUIPE: 833006 - DLP-MPPA01 ENCARREGADO: IBANEZ RODRIGUES DATA: 22/08/2026
A6: ETO-RD-GR 00632/2026 | B6: jun | C6: Sem interrupção comprovada | D6: Sem interrupção | E6: EXPURGO | F6: QUEIMADO | G6: esteira 1.582 | H6: AUSENTE DA CRÍTICA | I6: 5700782153 | J6: ENC-MLGR01 000151/2026 | K6: 712600426 | L6: 2026-06-19 15:57 | M6: 2026-06-20 14:13 | N6: FORMS SUBST DE TRANSFORMADOR | O6: ETO-RD-GR | P6: BERNARDO SAYAO | Q6: QUEIMADO | R6: NÃO IDENTIFICADO | S6: 846016 | T6: 830326 | U6: sim | V6: CONDUTOR DE AT | W6: PARTIDO NA FASE | Z6: SIM | AA6: leitura caso a caso | AB6: Fora do indicador: a Crítica nunca registrou defeito aberto neste transformador — em data nenhuma dos sete meses. O código aparece na base, mas só como interrompido ou manobrado, que é o que acontece com quem fica sem energia por defeito de outro equipamento. | AC6: TRANSFORMADOR DE 10KVA NA 34,5KV, QUEIMADO, ACESSO CAMINHONETE. | AD6: TROCA DE TRAFO QUEIMADO 5700782153 ETO-RD-GR 632/2026 ZONA RURAL - BERNARDO SAYÃO 0153 TRAFO RETIRADO POTÊNCIA : 10KVA TENSÃO : 19.9KV Nº ENERGISA (CITD) : CITD06012557 Nº DE SÉRIE : 896016 MARCA : ITB DATA FABRICAÇÃO : 05/2014 IMPEDANCIA : 3.00 POS. TAP : 01 TRAFO INSTALADO POTÊNCIA : 15KVA TENSÃO : 19.9KV Nº ENERGISA (CITD) : 151971 Nº DE SÉRIE : 830326 MARCA : TRAEL DATA FABRICAÇÃO : 04/2026 IMPEDANCIA : 3.0 POS. TAP : 03 MEDIÇÃO 1: 26.94 MEDIÇÃO 2: 22.75 MEDIÇÃO 3: 18.57 COORDENADA X: 701966 Y: 9118821
A7: ENC-RD-PS 00594/2026 | B7: jun | C7: Sem interrupção comprovada | D7: Sem interrupção | E7: EXPURGO | F7: QUEIMADO | G7: esteira 1.582 | H7: AUSENTE DA CRÍTICA | I7: 5700417110 | J7: ENC-LMPS03 000095/2026 | K7: 212600540 | L7: 2026-06-21 13:30 | M7: 2026-06-22 19:24 | N7: FORMS SUBST DE TRANSFORMADOR | O7: ENC-RD-PS | P7: SANTA RITA DO TOCANTINS | Q7: QUEIMADO | R7: NÃO IDENTIFICADO | S7: 462535 | T7: 822924 | U7: sim | Z7: SIM | AA7: leitura caso a caso | AB7: Fora do indicador: o código não aparece na Crítica em papel nenhum — nem com defeito, nem interrompido, nem manobrado — nos sete meses do acervo; nem o teste do vizinho achou explicação. | AC7: TRAFO 5700417110 DE 5 KVA NA REDE 19.9 KV QUEIMADO ACESSO BOM TROCAR E O POSTE DO TRAFO ID: 47152336 POIS O MESMO NÃO SUPORTA O TRAFO DE 15 E FINO E O POSTE ANTES DA CHAVE TRAFO 0300417110 NO ID: 68938875 PARA FAZER O SERVIÇO TEM ABRIR CHAVE LAMINA PROXIMO AO TRAFO 5700399073. | AD7: SS ENC-RD-PS 594/2026 TRAFO 5700417110 TRAFO RETIRADO POTÊNCIA : 5KVA TENSÃO : 34.5KV Nº ENERGISA (CITD) : 21593 Nº DE SÉRIE : 462535 MARCA : ITB DATA FABRICAÇÃO : 06/2007 IMPEDANCIA : 2.43 POS. TAP : 02 TRAFO INSTALADO' POTÊNCIA : 15KVA TENSÃO : 34.5KV Nº ENERGISA (CITD) : 149489 Nº DE SÉRIE : 822924 MARCA : TRAEL DATA FABRICAÇÃO : 03/2026 IMPEDANCIA : 3.0 POS. TAP : 03
A8: ENC-RD-PS 00546/2026 | B8: jun | C8: Sem interrupção comprovada | D8: Sem interrupção | E8: EXPURGO | F8: QUEIMADO | G8: esteira 1.582 | H8: AUSENTE DA CRÍTICA | I8: 5701119075 | J8: ENC-LMPS03 000087/2026 | K8: 212600505 | L8: 2026-06-01 16:44 | M8: 2026-06-02 17:57 | N8: FORMS SUBST DE TRANSFORMADOR | O8: ENC-RD-PS | P8: DOIS IRMAOS DO TOCANTINS | Q8: AVARIADO | R8: VAZAMENTO DE ÓLEO | S8: 379996 | U8: não | Z8: SIM | AA8: leitura caso a caso | AB8: Fora do indicador: o ativo não existe na base de interrupção. Sem registro de interrupção não há evento a medir. | AC8: 5701119075 15KVA 34,5KV ACESSO BOM E PARA-RAIOS 075OP02 | AD8: SS ENC-RD-PS 546/2026 TRAFO: 5701119075 TRAFO RETIRADO POTÊNCIA : 15KVA TENSÃO : 34.5KV Nº ENERGISA (CITD) : 035368 Nº DE SÉRIE : 379996 MARCA : TRAEL DATA FABRICAÇÃO : 04/2016 IMPEDANCIA : 2.87 POS. TAP : 03 TRAFO INSTALADO' POTÊNCIA : 15KVA TENSÃO : 34.5KV Nº ENERGISA (CITD) : 151648 Nº DE SÉRIE : C 308217 MARCA : ITAM DATA FABRICAÇÃO : 4/2026 IMPEDANCIA : 3.23 POS. TAP : 03
A9: DOLP-RD-PA 00621/2026 | B9: jun | C9: Sem interrupção comprovada | D9: Sem interrupção | E9: EXPURGO | F9: QUEIMADO | G9: esteira 1.582 | H9: AUSENTE DA CRÍTICA | I9: 5711684122 | J9: DLP-MLPA03 000083/2026 | K9: 112600598 | L9: 2026-06-01 12:34 | M9: 2026-05-22 18:00 | N9: FORMS SUBST DE TRANSFORMADOR | O9: DOLP-RD-PA | P9: PALMAS | Q9: QUEIMADO | R9: DESCARGA ATMOSFÉRICA | S9: 361897 | T9: 303259 | U9: sim | Z9: SIM | AA9: leitura caso a caso | AB9: Fora do indicador: o ativo não existe na base de interrupção. Sem registro de interrupção não há evento a medir. | AC9: TRAFO 5711684122 QUEIMADOPOTÊNCIA: 15 KVATENSÃO: 19,9 KVACESSO: LIVRE | AD9: MEDIDO_ EMERGENCIAL_ TRAFO 5711684122 QUEIMADO - POTÊNCIA: 15 KVA - TENSÃO: 19,9 KV - ACESSO: LIVRE DADOS ATENDIMENTO N° DOCUMENTO SS: DOLP-RD-PA 000621/2026 N° DOCUMENTO OS: DLP-MLPA03 000083/2026 TIPO DA INTERVENÇÃO: MANUTENÇÃO TIPO DO SERVIÇO: SUBSTITUIÇÃO DE TRANSFORMADOR E MELHORIA DE MALHA DE ATERRAMENTO DATA PROGRAMADA DA ATIVIDADE: 02/06/2026 HORARIO PREVISTO DA ATIVIDADE: 08:00 ÀS 18:00 CIDADE: PALMAS - CLASSE DE TENSÃO: 19,9KV ALIMENTADOR: LD02059122 - TRANSFORMADOR: 5711684122 EQUIPE: DOLP-MLPA04 CONTATO DA EQUIPE: 63 9295-4214 COMPOSIÇÃO DA EQUIPE: 1
A10: ETO-RD-AR 00872/2026 | B10: mai | C10: Sem interrupção comprovada | D10: Sem interrupção | E10: EXPURGO | F10: QUEIMADO | G10: esteira 1.582 | H10: AUSENTE DA CRÍTICA | I10: 5710241016 | J10: ENC-MLAR01 000202/2026 | K10: 612600532 | L10: 2026-05-17 17:55 | M10: 2026-05-18 16:15 | N10: FORMS SUBST DE TRANSFORMADOR | O10: ETO-RD-AR | P10: WANDERLANDIA | Q10: QUEIMADO | R10: DESCARGA ATMOSFÉRICA | S10: 66567 | T10: 469632 | U10: sim | V10: MEIO AMBIENTE | W10: DESCARGA ATMOSFERICA | Z10: SIM | AA10: leitura caso a caso | AB10: Fora do indicador: a Crítica nunca registrou defeito aberto neste transformador — em data nenhuma dos sete meses. O código aparece na base, mas só como interrompido ou manobrado, que é o que acontece com quem fica sem energia por defeito de outro equipamento. | AC10: Trafo 5710241016 Queimado Potencia: 10 KVATensão: 34,5 KVPara raio: Queimado Acesso: livreEquipe: 004op26 (63)99214-9597 | AD10: ETO-RD-AR 872/2026 TRAFO 5710241016 TRAFO RETIRADO POTÊNCIA : 10 KVA TENSÃO : 34.5 KV Nº ENERGISA (CITD) : ILEGIVEL Nº DE SÉRIE : 66567 MARCA : TRAEL DATA FABRICAÇÃO : 10/2005 IMPEDANCIA : 3,01 POS. TAP : 03 TRAFO INSTALADO POTÊNCIA : 15 KVA TENSÃO : 34.5 KV Nº ENERGISA (CITD) : 149646 Nº DE SÉRIE : 469632 MARCA : TRAEL DATA FABRICAÇÃO : 05/2018 IMPEDANCIA : 2,89 POS. TAP : 05
A11: ETO-RD-AG 00508/2026 | B11: mai | C11: Sem interrupção comprovada | D11: Sem interrupção | E11: EXPURGO | F11: QUEIMADO | G11: esteira 1.582 | H11: AUSENTE DA CRÍTICA | I11: 5701508039 | J11: ENC-MLAG01 000127/2026 | K11: 662600315 | L11: 2026-05-15 13:32 | M11: 2026-05-16 23:48 | N11: FORMS SUBST DE TRANSFORMADOR | O11: ETO-RD-AG | P11: ARAGUATINS | Q11: QUEIMADO | R11: DESCARGA ATMOSFÉRICA | S11: 125111 | U11: não | Z11: SIM | AA11: leitura caso a caso | AB11: Fora do indicador: o ativo não existe na base de interrupção. Sem registro de interrupção não há evento a medir. | AC11: trafo queimado 5701508039 - 15KVA - 34,5KV - para raio queimado - acesso caminhonete. IND CHACARA BOA ESPERANCA - cliente: JUNHO ALVES DE SOUSA - 63992753298REF PROX AO PEQUENO E AO VALDINAR RDR ARAGUATINS | AD11: OS PARA S6BSTITUICAO DE TRAFO QUEIMADO trafo queimado 5701508039 - 15KVA - 34,5KV - para raio queimado - acesso caminhonete. IND CHACARA BOA ESPERANCA - cliente: JUNHO ALVES DE SOUSA - 63992753298 REF PROX AO PEQUENO E AO VALDINAR RDR ARAGUATINS TRAFO Nº 5701508039 TRAFO INSTALADO POTÊNCIA; 05KVA 34,5KV DATA DE FAB; AGOSTO/2008 MARCA; VIJAI Nº CITD; N/A Nº SÉRIE; 125111 POS. DO TAP; 5 IMPEDÃNCIA; 2,99 TRAFO RETIRADO POTÊNCIA; 15KVA 34,5KV DATA DE FAB; 24/01/2026 MARCA; ITAM Nº CITD; 147933 Nº SÉRIE; C.299646 POS. DO TAP; 3] IMPEDÃNCIA; 2,84 ME
A12: ETO-RD-AG 00489/2026 | B12: mai | C12: Sem interrupção comprovada | D12: Sem interrupção | E12: EXPURGO | F12: QUEIMADO | G12: esteira 1.582 | H12: AUSENTE DA CRÍTICA | I12: 5701350103 | J12: ENC-MLAG01 000121/2026 | K12: 662600297 | L12: 2026-05-08 12:16 | M12: 2026-05-11 08:35 | N12: FORMS SUBST DE TRANSFORMADOR | O12: ETO-RD-AG | P12: SAO MIGUEL DO TOCANTINS | Q12: AVARIADO | R12: BUCHA DANIFICADA | S12: 184716 | T12: 828146 | U12: sim | Z12: SIM | AA12: leitura caso a caso | AB12: Fora do indicador: o ativo não existe na base de interrupção. Sem registro de interrupção não há evento a medir. | AC12: Segue SS de transformador 5701350103 Queimado Potencia 10 KVA Tensão: 19.9 KVAcesso livre Fazenda Jangada. Assentamento Camarão II | AD12: OS PARA SUBSTITUICAO DE TRAFO QUEIMADO Segue SS de transformador 5701350103 Queimado Potencia 10 KVA Tensão: 19.9 KV Acesso livre Fazenda Jangada. Assentamento Camarão II TRAFO Nº 5701350103 TRANSFORMAR RETIRADO POTÊNCIA; 05KVA 34,5KV DATA DE FAB; FEV/2011 MARCA; VIJAI Nº CITD; N/A Nº SÉRIE; 184716 POS. DO TAP; 3º IMPEDÂNCIA; 3,14 TRAFO INSTALADO POTÊNCIA; 15KVA 34,5KV DATA DE FAB; FEV/2026 MARCA; TRAEL Nº CITD; 150423 Nº SÉRIE; 828146 POS. DO TAP; 3º IMPEDÂNCIA; 3 MEDIÇÃO; 3,37 / 3,36 / 3,34
A13: DOLP-RD-PA 00588/2026 | B13: mai | C13: Sem interrupção comprovada | D13: Sem interrupção | E13: EXPURGO | F13: QUEIMADO | G13: esteira 1.582 | H13: AUSENTE DA CRÍTICA | I13: 5761649196 | J13: DLP-CTPA01 000043/2026 | K13: 112600559 | L13: 2026-05-24 00:11 | M13: 2026-05-24 18:00 | N13: FORMS SUBST DE TRANSFORMADOR | O13: DOLP-RD-PA | P13: LAGOA DO TOCANTINS | Q13: QUEIMADO | R13: NÃO IDENTIFICADO | S13: 0 | T13: 0 | U13: não | V13: TRANSFORMADOR | W13: QUEIMADO POR CAUSA NAO IDENTIFICADA | Z13: SIM | AA13: leitura caso a caso | AB13: Fora do indicador: a Crítica nunca registrou defeito aberto neste transformador — em data nenhuma dos sete meses. O código aparece na base, mas só como interrompido ou manobrado, que é o que acontece com quem fica sem energia por defeito de outro equipamento. | AC13: TRAFO QUEIMADO | AD13: MEDIDO_ 01. Baixado para consumo de materiais TRAFO QUEIMADO 75kva NA 34,5KV, REFAZER PIRATICS DO TRANSFORMADO OBS: CIRCUITO DO TRANSFROMADO QUEIMADO EST SENDO ENEGISADO POR OUTRO CIRCUITO, FOI FECHADO JUMP NO LOCAL. ATENÇÃO: VERIFICAR CONDIÇOES DO BARRAMENTO É ATERRAMENTO ATIVO:190.02811475 LOOCALIZAÇÃO: 351531 EQUIPE: CTPA-05 ENCARREGADO: JOSE AILTON TEL: 63 99296-7029
A14: DOLP-RD-PA 00552/2026 | B14: mai | C14: Sem interrupção comprovada | D14: Sem interrupção | E14: EXPURGO | F14: QUEIMADO | G14: esteira 1.582 | H14: AUSENTE DA CRÍTICA | I14: 5365343122 | J14: DLP-MLPA01 000157/2026 | K14: 112600511 | L14: 2026-05-12 17:38 | M14: 2026-05-13 18:00 | N14: FORMS SUBST DE TRANSFORMADOR | O14: DOLP-RD-PA | P14: PALMAS | S14: 1600171 | T14: 299975 | U14: sim | Z14: SIM | AA14: leitura caso a caso | AB14: Fora do indicador: o ativo não existe na base de interrupção. Sem registro de interrupção não há evento a medir. | AC14: segue ss de 01 trafo de 25 kvar e 01 para raio queimado da rede de 13.800kv e para raio queimado para ser subistituido pela equipe de manutencão acesso livre equipe que atendeu 059op14 cel, 63992432595/985159679 chave de referencia, 5365343122 | AD14: MEDIDO_ EMERGENCIAL_ segue ss de 01 trafo de 25 kvar e 01 para raio queimado da rede de 13.800kv e para raio queimado para ser subistituido pela equipe de manutencão acesso livre equipe que atendeu 059op14 cel, 63992432595/985159679 chave de referencia, 5365343122 DADOS ATENDIMENTO N° DOCUMENTO SS: DOLP-RD-PA 000552/2026 N° DOCUMENTO OS: DLP-MLPA01 000157/2026 TIPO DA INTERVENÇÃO: MANUTENÇÃO TIPO DO SERVIÇO: SUBSTITUIÇÃO DE TRANSFORMADOR E MELHORIA DE MALHA DE ATERRAMENTO DATA PROGRAMADA DA ATIVIDADE: 13/05/2026 HORARIO PREVISTO DA ATIVIDADE: 08:00 ÀS 18:00 CIDADE: PA
A15: ETO-RD-GU 00440/2026 | B15: abr | C15: Sem interrupção comprovada | D15: Sem interrupção | E15: EXPURGO | F15: QUEIMADO | G15: esteira 1.582 | H15: AUSENTE DA CRÍTICA | I15: 5700284148 | J15: DBM-MLDB05 000086/2026 | K15: 412600378 | L15: 2026-04-07 18:19 | M15: 2026-04-08 20:00 | N15: FORMS SUBST DE TRANSFORMADOR | O15: ETO-RD-GU | P15: SAO VALERIO | Q15: SOBRECARGA PREVENTIVA | R15: NÃO IDENTIFICADO | S15: 1025954 | T15: 827970 | U15: sim | Z15: não | AA15: leitura caso a caso | AB15: Fora do indicador: o ativo não existe na base de interrupção. Sem registro de interrupção não há evento a medir. | AC15: SEGUE SS DE TRAFO QUEIMADO NA RDR DE SAO VALERIO, TRAFO DE 15KVA NA REDE DE 19.9KV, TRAFO E PARARAIO QUEIMADO, ACESSO LIVRE PARA CAMINHONETE. | AD15: SUBSTITUIÇÃO DE TRANSFORMADOR NA RDR DE SÃO VALÉRIO INT: 20264266691405 SS: ETO-RD-GU 440/2026 ESPECIFICAÇÕES DO TRANSFORMADOR TRANSFORMADOR INSTALADO: 15KVA TRANSFORMADOR RETIRADO: 15KVA MEDIÇÕES LOGO APÓS A TROCA VAN: 212.1 VBN: 221.4 VAB: 420 OBS:SUBSTITUIÇÃO DE TRANSFORMADOR AUTORIZADA PELO DIONE. OBS:FOI FEITO A SEGUNDA DESCIDA DO ATERRAMENTO NO TRANSFORMADOR
A16: ETO-RD-GR 00400/2026 | B16: abr | C16: Sem interrupção comprovada | D16: Sem interrupção | E16: EXPURGO | F16: QUEIMADO | G16: esteira 1.582 | H16: AUSENTE DA CRÍTICA | I16: 5700214066 | J16: ENC-MPGR01 000062/2026 | K16: 712600282 | L16: 2026-04-03 10:19 | M16: 2026-04-03 21:05 | N16: FORMS SUBST DE TRANSFORMADOR | O16: ETO-RD-GR | P16: TUPIRATINS | Q16: QUEIMADO | R16: DESCARGA ATMOSFÉRICA | S16: 389793 | T16: 828102 | U16: sim | Z16: não | AA16: leitura caso a caso | AB16: Fora do indicador: o código não aparece na Crítica em papel nenhum — nem com defeito, nem interrompido, nem manobrado — nos sete meses do acervo; nem o teste do vizinho achou explicação. | AC16: acionar equipe de manutencao para troca do poste e transformador no RDR de [0066] TUPIRATINStrafo 5700214066poste 10-300 id.: 49935819 estrutura u3-Tequipe 034op03 | AD16: TROCA DE TRAFO QUEIMADO 5700214066 ETO-RD-GR 400/2026 ZONA RURAL - TUPIRATINS 0066 TRAFO RETIRADO POTÊNCIA : 15KVA TENSÃO : 19.9KV Nº ENERGISA (CITD) : CITD061006 Nº DE SÉRIE : 389793 MARCA : TRAEL DATA FABRICAÇÃO : 06/2016 IMPEDANCIA : 2.92 POS. TAP : 03 TRAFO INSTALADO POTÊNCIA : 15KVA TENSÃO : 19.9KV Nº ENERGISA (CITD) : 150379 Nº DE SÉRIE : 828102 MARCA : TRAEL DATA FABRICAÇÃO : 02/2026 IMPEDANCIA : 3.0 POS. TAP : 03 MEDIÇÃO 1: 00.15 MEDIÇÃO 2: 00.14 MEDIÇÃO 3: 00.12 COORDENADA X: 808852 Y: 9053576
A17: ETO-RD-DP 00248/2026 | B17: abr | C17: Sem interrupção comprovada | D17: Sem interrupção | E17: EXPURGO | F17: QUEIMADO | G17: esteira 1.582 | H17: AUSENTE DA CRÍTICA | I17: 5700456038 | J17: ETO-RD-DP 000760/2026 | K17: 512600133 | L17: 2026-04-19 12:14 | M17: 2026-04-24 12:22 | N17: FORMS SUBST DE TRANSFORMADOR | O17: ETO-RD-DP | P17: TAGUATINGA | Q17: AVARIADO | R17: BUCHA DANIFICADA | S17: 180034 | T17: 820162 | U17: sim | V17: MEIO AMBIENTE | W17: DESCARGA ATMOSFERICA | Z17: SIM | AA17: leitura caso a caso | AB17: Fora do indicador: a Crítica nunca registrou defeito aberto neste transformador — em data nenhuma dos sete meses. O código aparece na base, mas só como interrompido ou manobrado, que é o que acontece com quem fica sem energia por defeito de outro equipamento. | AC17: trafo e para raio queimado 5700456038 15kva 19.9kv faz.oriente rdr de taguatinga equipe 038op01 | AD17: Atendida pela equipe ETO ML DP 02
A18: ETO-RD-AR 00775/2026 | B18: abr | C18: Sem interrupção comprovada | D18: Sem interrupção | E18: EXPURGO | F18: QUEIMADO | G18: esteira 1.582 | H18: AUSENTE DA CRÍTICA | I18: 5700702019 | J18: ENC-MLAR02 000091/2026 | K18: 612600471 | L18: 2026-04-30 11:15 | M18: 2026-04-30 18:12 | N18: FORMS SUBST DE TRANSFORMADOR | O18: ETO-RD-AR | P18: FILADELFIA | Q18: QUEIMADO | R18: VAZAMENTO DE ÓLEO | S18: 126189 | T18: 799422 | U18: sim | Z18: SIM | AA18: leitura caso a caso | AB18: Fora do indicador: o código não aparece na Crítica em papel nenhum — nem com defeito, nem interrompido, nem manobrado — nos sete meses do acervo; nem o teste do vizinho achou explicação. | AC18: Trafo 5700702019 15kvaAcesso: Livre Equipe:019op02Contato da equipe : 99242-6260 | AD18: ETO-RD-AR 775/2026 TRAFO 5700702019 TRAFO RETIRADO POTÊNCIA : 5 KVA TENSÃO : 34.5 KV Nº ENERGISA (CITD) : ILEGIVEL Nº DE SÉRIE : 126189 MARCA : VIJAI DATA FABRICAÇÃO : 09/2008 IMPEDANCIA : 3,13 POS. TAP : 05 TRAFO INSTALADO POTÊNCIA : 15 KVA TENSÃO : 34.5 KV Nº ENERGISA (CITD) : 150762 Nº DE SÉRIE : 799422 MARCA : TRAEL DATA FABRICAÇÃO : 10/2025 IMPEDANCIA : 3,0 POS. TAP : 05
A19: ETO-RD-AR 00773/2026 | B19: abr | C19: Sem interrupção comprovada | D19: Sem interrupção | E19: EXPURGO | F19: QUEIMADO | G19: esteira 1.582 | H19: AUSENTE DA CRÍTICA | I19: 5700290030 | J19: ENC-MLAR05 000206/2026 | K19: 612600472 | L19: 2026-04-29 18:02 | M19: 2026-04-30 15:53 | N19: FORMS SUBST DE TRANSFORMADOR | O19: ETO-RD-AR | P19: PIRAQUE | Q19: QUEIMADO | R19: SOBRECARGA | S19: 185261 | T19: 822886 | U19: sim | Z19: SIM | AA19: leitura caso a caso | AB19: Fora do indicador: o ativo não existe na base de interrupção. Sem registro de interrupção não há evento a medir. | AC19: TRAFO QUEIMADO 5700920030POTENCIA: 5KVATENSÃO: 34,5KVACESSO BOM.PARA-RAIO QUEIMADO.FAZ. MORENA 1 | AD19: ETO-RD-AR 773/2026 TRAFO 5700920030 TRAFO RETIRADO POTÊNCIA : 05 KVA TENSÃO : 34.5 KV Nº ENERGISA (CITD) : 185261 Nº DE SÉRIE : S/N MARCA : S/N DATA FABRICAÇÃO : S/N IMPEDANCIA : S/N POS. TAP : S/N TRAFO INSTALADO POTÊNCIA : 15 KVA TENSÃO : 34.5 KV Nº ENERGISA (CITD) : 14945 Nº DE SÉRIE : 822886 MARCA : TRAEL DATA FABRICAÇÃO : 02/2026 IMPEDANCIA : 3,0 POS. TAP : 05
A20: ETO-RD-AR 00763/2026 | B20: abr | C20: Sem interrupção comprovada | D20: Sem interrupção | E20: EXPURGO | F20: QUEIMADO | G20: esteira 1.582 | H20: AUSENTE DA CRÍTICA | I20: 5710235080 | J20: ENC-MPAR01 000046/2026 | K20: 612600464 | L20: 2026-04-29 08:53 | M20: 2026-04-28 15:50 | N20: AVISO DE ANOMALIA | O20: ETO-RD-AR | P20: DARCINOPOLIS | Q20: QUEIMADO | R20: DESCARGA ATMOSFÉRICA | S20: 690163 | T20: 822876 | U20: sim | Z20: não | AA20: leitura caso a caso | AB20: Fora do indicador: o ativo não existe na base de interrupção. Sem registro de interrupção não há evento a medir. | AC20: NOTA ABERTA PARA CORREÇÃO DA SS 751/2026 POIS O TRAFO QUE ESTAVA QUEIMADO E O 5710235080 | AD20: ETO-RD-AR 763/2026 TRAFO 5710235080 TRAFO RETIRADO POTÊNCIA : 15 KVA TENSÃO : 34.5 KV Nº ENERGISA (CITD) : 39532 Nº DE SÉRIE : 690163 MARCA : ITB DATA FABRICAÇÃO : 08/2010 IMPEDANCIA : 3,19 POS. TAP : 05 TRAFO INSTALADO POTÊNCIA : 15 KVA TENSÃO : 34.5 KV Nº ENERGISA (CITD) : 149441 Nº DE SÉRIE : 822876 MARCA : TRAEL DATA FABRICAÇÃO : 02/2026 IMPEDANCIA : 3,0 POS. TAP : 05 MEDIÇÃO 1:19.38 MEDIÇÃO 2:18.87 MEDIÇÃO 3:15.24
A21: ETO-RD-AR 00702/2026 | B21: abr | C21: Sem interrupção comprovada | D21: Sem interrupção | E21: EXPURGO | F21: QUEIMADO | G21: esteira 1.582 | H21: AUSENTE DA CRÍTICA | I21: 5701086022 | J21: ENC-MLAR01 000190/2026 | K21: 612600425 | L21: 2026-04-18 17:12 | M21: 2026-04-19 11:35 | N21: FORMS SUBST DE TRANSFORMADOR | O21: ETO-RD-AR | P21: BABACULANDIA | Q21: QUEIMADO | R21: DESCARGA ATMOSFÉRICA | S21: E1274 | T21: 827915 | U21: sim | V21: CHAVE FUSIVEL/RELIGADORA | W21: PORTA-FUSIVEL DANIFICADO | X21: CHAVE FUSIVEL/RELIGADORA | Y21: PORTA-FUSIVEL DANIFICADO | Z21: SIM | AA21: leitura caso a caso | AB21: Fora do indicador: o dono mandou mover para ausente da base de interrupções. Conferido na Crítica crua: o código 5701086022 nunca teve defeito aberto nele em data nenhuma — aparece uma vez, e só como manobrado. Entrava pelo TMAE, e o próprio atendimento registra causa CHAVE FUSIVEL/RELIGADORA com subcausa porta-fusível danificado, não falha do transformador. | AC21: Trafo 5701086022 Queimado Potencia: 15 KVATensão: 34,5 KVPara raio: Queimado Acesso: livreEquipe: 022op02 (63)99255-6152Obs.: leva porta fusivel | AD21: ETO-RD-AR 702/2026 TRAFO 5701086022 TRAFO RETIRADO POTÊNCIA : 15 kva TENSÃO : 34.5 KV Nº ENERGISA (CITD) : P50027 Nº DE SÉRIE : E1274 MARCA : ELETROPAULO DATA FABRICAÇÃO : 05/2009 IMPEDANCIA : 3,0 POS. TAP : 03 TRAFO INSTALADO POTÊNCIA : 15 KVA TENSÃO : 34.5 KV Nº ENERGISA (CITD) : 150192 Nº DE SÉRIE : 827915 MARCA : TRAEL DATA FABRICAÇÃO : 02/2026 IMPEDANCIA : 3,0 POS. TAP : 05 MEDIÇÃO 1: 1.15 MEDIÇÃO 2: 2.04 MEDIÇÃO 3: 3.55 SUBST CHAVE FUSIVEL DANIFICADA 03101634022
A22: ETO-RD-AR 00700/2026 | B22: abr | C22: Sem interrupção comprovada | D22: Sem interrupção | E22: EXPURGO | F22: QUEIMADO | G22: esteira 1.582 | H22: AUSENTE DA CRÍTICA | I22: 5710170025 | J22: ENC-MPAR01 000026/2026 | K22: 612600429 | L22: 2026-04-17 14:38 | M22: 2026-04-18 15:56 | N22: FORMS SUBST DE TRANSFORMADOR | O22: ETO-RD-AR | P22: ARAPOEMA | Q22: QUEIMADO | R22: VAZAMENTO DE ÓLEO | S22: 1663552 | T22: 828161 | U22: sim | Z22: SIM | AA22: leitura caso a caso | AB22: Fora do indicador: o ativo não existe na base de interrupção. Sem registro de interrupção não há evento a medir. | AC22: trafo 5710170025 queimado acesso bom para caminhonete 25kvaequipe 025op01 | AD22: ETO-RD-AR 700/2026 TRAFO 5710170025 TRAFO RETIRADO POTÊNCIA : 25 KVA TENSÃO : 34.5 KV Nº ENERGISA (CITD) : ILEGIVEL Nº DE SÉRIE : 186352 MARCA : UNIÃO DATA FABRICAÇÃO : 09/2001 IMPEDANCIA : 3,0 POS. TAP : 03 TRAFO INSTALADO POTÊNCIA : 25 KVA TENSÃO : 34.5 KV Nº ENERGISA (CITD) : 150438 Nº DE SÉRIE : 828161 MARCA : TRAEL DATA FABRICAÇÃO : 02/2026 IMPEDANCIA : 3,0 POS. TAP : 05 MEDIÇÃO 1: MEDIÇÃO 2: MEDIÇÃO 3:
A23: ETO-RD-AR 00658/2026 | B23: abr | C23: Sem interrupção comprovada | D23: Sem interrupção | E23: EXPURGO | F23: QUEIMADO | G23: esteira 1.582 | H23: AUSENTE DA CRÍTICA | I23: 5761134022 | J23: ENC-MLAR01 000177/2026 | K23: 612600400 | L23: 2026-04-10 10:56 | M23: 2026-04-10 14:49 | N23: FORMS SUBST DE TRANSFORMADOR | O23: ETO-RD-AR | P23: BABACULANDIA | Q23: QUEIMADO | R23: NÃO IDENTIFICADO | S23: 581755 | T23: 1319660 | U23: sim | Z23: SIM | AA23: leitura caso a caso | AB23: Fora do indicador: o ativo não existe na base de interrupção. Sem registro de interrupção não há evento a medir. | AC23: trafo 5761134022 75kva 34.5kv queimado | AD23: ETO-RD-AR 658/2026 TRAFO 5761134022 TRAFO RETIRADO POTÊNCIA : 75 KVA TENSÃO : 34.5 KV Nº ENERGISA (CITD) : 303445 Nº DE SÉRIE : 581755 MARCA : TRAEL DATA FABRICAÇÃO : 06/2021 IMPEDANCIA : 4,02 POS. TAP : 04 TRAFO INSTALADO POTÊNCIA : 75 KVA TENSÃO : 34.5 KV Nº ENERGISA (CITD) : 129465 Nº DE SÉRIE : 1319660 MARCA : ROMAGNOLE DATA FABRICAÇÃO : 2021 IMPEDANCIA : 3,99 POS. TAP : 04
A24: ENC-RD-PS 00438/2026 | B24: abr | C24: Sem interrupção comprovada | D24: Sem interrupção | E24: EXPURGO | F24: QUEIMADO | G24: esteira 1.582 | H24: AUSENTE DA CRÍTICA | I24: 5701060070 | J24: ENC-LMPS04 000063/2026 | K24: 212600400 | L24: 2026-04-07 15:20 | M24: 2026-04-08 15:45 | N24: FORMS SUBST DE TRANSFORMADOR | O24: ENC-RD-PS | P24: RIO SONO | Q24: QUEIMADO | R24: DESCARGA ATMOSFÉRICA | S24: 482388 | T24: 827361 | U24: sim | Z24: SIM | AA24: leitura caso a caso | AB24: Fora do indicador: o ativo não existe na base de interrupção. Sem registro de interrupção não há evento a medir. | AC24: Segue SS de trafo 5701096007 queimado para devidas trativas com equipe de manutenção.Potencia 15 kvatensão 34.5kv para raio bomacesso livre OBS: trafo com erro de cadastro, o mesmo esta cadastrado na rededa 13.8 porem em campo esta ligado na rede da 34.5 kv. trafo fica localizado ao lado do trafo 5700487007 | AD24: SS ENC-RD-PS 438/2026 trafo 5700487007 TRAFO RETIRADO POTÊNCIA : 15KVA TENSÃO : 34.5KV Nº ENERGISA (CITD) : 06118154 Nº DE SÉRIE : 482388 MARCA : TRAEL DATA FABRICAÇÃO : AGO/2018 IMPEDANCIA : 2.92 POS. TAP : 03 TRAFO INSTALADO' POTÊNCIA : 15KVA TENSÃO : 34.5KV Nº ENERGISA (CITD) : 150239 Nº DE SÉRIE : 827362 MARCA : TRAEL DATA FABRICAÇÃO : 02/2026 IMPEDANCIA : 3.0 POS. TAP : 03
A25: DOLP-RD-PA 00437/2026 | B25: abr | C25: Sem interrupção comprovada | D25: Sem interrupção | E25: EXPURGO | F25: QUEIMADO | G25: esteira 1.582 | H25: AUSENTE DA CRÍTICA | I25: 5704106122 | J25: DLP-CTPA00 000069/2026 | K25: 112600401 | L25: 2026-04-09 12:30 | M25: 2026-04-09 18:00 | N25: FORMS SUBST DE TRANSFORMADOR | O25: DOLP-RD-PA | P25: PALMAS | Q25: QUEIMADO | R25: DESCARGA ATMOSFÉRICA | S25: 0 | T25: 0 | U25: não | Z25: SIM | AA25: leitura caso a caso | AB25: Fora do indicador: a Crítica nunca registrou defeito aberto neste transformador — em data nenhuma dos sete meses. O código aparece na base, mas só como interrompido ou manobrado, que é o que acontece com quem fica sem energia por defeito de outro equipamento. | AC25: segue nota de trafo queimado, trafo 5704106122, trafo de 45kva, tensao 13800 / 380 V, para raio danificado, acesso livre | AD25: MEDIDO_ 01. Baixado para consumo de material segue nota de trafo queimado, trafo 5704106122, trafo de 45kva, tensao 13800 / 380 V, para raio danificado, acesso livre DADOS DO ATENDIMENTO: EQUIPE: 833021 - DOLP-CT-PA11 ENCARREGADO: PAFILO ANDALECIO DATA: 09/04/2026
A26: DG-RD-PO 00333/2026 | B26: abr | C26: Sem interrupção comprovada | D26: Sem interrupção | E26: EXPURGO | F26: QUEIMADO | G26: esteira 1.582 | H26: AUSENTE DA CRÍTICA | I26: 5700494044 | J26: DG-MLPO02 000062/2026 | K26: 312600263 | L26: 2026-04-14 17:47 | M26: 2026-04-15 11:50 | N26: FORMS SUBST DE TRANSFORMADOR | O26: DG-RD-PO | P26: FATIMA | Q26: QUEIMADO | R26: BUCHA DANIFICADA | S26: 186148 | T26: 827744 | U26: sim | V26: MEIO AMBIENTE | W26: DESCARGA ATMOSFERICA | Z26: SIM | AA26: leitura caso a caso | AB26: Fora do indicador: a Crítica nunca registrou defeito aberto neste transformador — em data nenhuma dos sete meses. O código aparece na base, mas só como interrompido ou manobrado, que é o que acontece com quem fica sem energia por defeito de outro equipamento. | AC26: ss para trocar trafo 5700494044 e para raio queimado POTENCIA: 15KVA 7.9KVACESSO CAMINHONETE, CARRO FICA A 30 METROS DO LOCAL | AD26: medido_ emergencial_ substituição de trafo queimado rdr fatima
A27: ETO-RD-GU 00377/2026 | B27: mar | C27: Sem interrupção comprovada | D27: Sem interrupção | E27: EXPURGO | F27: QUEIMADO | G27: esteira 1.582 | H27: AUSENTE DA CRÍTICA | I27: 5731386073 | J27: ETO-RD-GU 000932/2026 | K27: 412600315 | L27: 2026-03-23 18:27 | M27: 2026-03-25 15:50 | N27: FORMS SUBST DE TRANSFORMADOR | O27: ETO-RD-GU | P27: LAGOA DA CONFUSAO | Q27: QUEIMADO | R27: DESCARGA ATMOSFÉRICA | S27: 368891 | T27: 827891 | U27: sim | V27: TRANSFORMADOR | W27: QUEIMADO POR CAUSA NAO IDENTIFICADA | Z27: SIM | AA27: leitura caso a caso | AB27: Fora do indicador: a Crítica nunca registrou defeito aberto neste transformador — em data nenhuma dos sete meses. O código aparece na base, mas só como interrompido ou manobrado, que é o que acontece com quem fica sem energia por defeito de outro equipamento. | AC27: TRAFO 5731386073 QUEIMADO EM CAMPO DE 15 KVA ACESSO APENAS DE BARCO REGIAO ALAGADAPARA RAIO QUEIMADO . | AD27: SS: ETO-RD-GU 377-2026 LOCALIDADE: LAGOA DA CONFUSÃO FOI FEITO A TROCA DE UM TRANSFORMADOR DE 15KVA POR 15KVA
A28: ETO-RD-AR 00582/2026 | B28: mar | C28: Sem interrupção comprovada | D28: Sem interrupção | E28: EXPURGO | F28: QUEIMADO | G28: esteira 1.582 | H28: AUSENTE DA CRÍTICA | I28: 5710015080 | J28: ENC-MLAR03 000042/2026 | K28: 612600374 | L28: 2026-03-31 20:03 | M28: 2026-04-02 14:50 | N28: FORMS SUBST DE TRANSFORMADOR | O28: ETO-RD-AR | P28: DARCINOPOLIS | Q28: QUEIMADO | R28: SOBRECARGA | S28: 533216 | T28: 828055 | U28: sim | Z28: SIM | AA28: leitura caso a caso | AB28: Fora do indicador: o ativo não existe na base de interrupção. Sem registro de interrupção não há evento a medir. | AC28: Trafo: 5710015080 QueimadoPotência: 15 KVARede: 34.5Pararaio: 34.5Acesso: só pra veículo traçadoSubstituir o mesmo pois está com a bucha primária quebrado por descarga atmosférica | AD28: ETO-RD-AR 582/2026 TRAFO 5710015080 TRAFO RETIRADO POTÊNCIA : 15 KVA TENSÃO : 3465 KV Nº ENERGISA (CITD) : 6123420 Nº DE SÉRIE : 533216 MARCA : TRAEL DATA FABRICAÇÃO : 03/2020 IMPEDANCIA : 3,0 POS. TAP : 05 TRAFO INSTALADO POTÊNCIA : 15 KVA TENSÃO : 34.5 KV Nº ENERGISA (CITD) : 150332 Nº DE SÉRIE : 828055 MARCA : TRAEL DATA FABRICAÇÃO : 02/2026 IMPEDANCIA : 3,0 POS. TAP : 05
A29: ETO-RD-AR 00557/2026 | B29: mar | C29: Sem interrupção comprovada | D29: Sem interrupção | E29: EXPURGO | F29: QUEIMADO | G29: esteira 1.582 | H29: AUSENTE DA CRÍTICA | I29: 5710138077 | J29: ENC-MLAR02 000072/2026 | K29: 612600344 | L29: 2026-03-26 08:51 | M29: 2026-03-27 18:00 | N29: FORMS SUBST DE TRANSFORMADOR | O29: ETO-RD-AR | P29: GOIATINS | Q29: AVARIADO | R29: SOBRECARGA | S29: 69463 | U29: não | Z29: SIM | AA29: leitura caso a caso | AB29: Fora do indicador: o ativo não existe na base de interrupção. Sem registro de interrupção não há evento a medir. | AC29: TR-5710138077 o mesmo não esta entregando a tensão adequadapara queimadopotência 10kvatensão 13,8kvacesso livreequipe 265op0 tel-63992212789 | AD29: ETO-RD-AR 557/2026 TRAFO 5710138077 TRAFO RETIRADO POTÊNCIA : 10 KVA TENSÃO : 13.8 KV Nº ENERGISA (CITD) : ILEGIVEL Nº DE SÉRIE :69463 MARCA : TRAEL DATA FABRICAÇÃO : 11/2005 IMPEDANCIA : 2,57 POS. TAP : 03 TRAFO INSTALADO POTÊNCIA : 15 KVA TENSÃO : 13.8 KV Nº ENERGISA (CITD) : 149841 Nº DE SÉRIE : C292465 MARCA : ITAM DATA FABRICAÇÃO : 10/2025 IMPEDANCIA : 2,75 POS. TAP : 05 OBS: LANÇADO UMA HORA DE DISPONIBILIDADE REFERENTE AO SERVIÇO DA SS 569/2026 PARA SEGURAR POSTE.
A30: ETO-RD-AR 00555/2026 | B30: mar | C30: Sem interrupção comprovada | D30: Sem interrupção | E30: EXPURGO | F30: QUEIMADO | G30: esteira 1.582 | H30: AUSENTE DA CRÍTICA | I30: 5702259004 | J30: ETO-RD-AR 000876/2026 | K30: 612600355 | L30: 2026-03-25 19:39 | M30: 2026-03-26 17:28 | N30: FORMS SUBST DE TRANSFORMADOR | O30: ETO-RD-AR | P30: ARAGUAINA | Q30: QUEIMADO | R30: NÃO IDENTIFICADO | U30: não | Z30: SIM | AA30: leitura caso a caso | AB30: Fora do indicador: a Crítica nunca registrou defeito aberto neste transformador — em data nenhuma dos sete meses. O código aparece na base, mas só como interrompido ou manobrado, que é o que acontece com quem fica sem energia por defeito de outro equipamento. | AC30: trafo queimado 5702259004 queimado 15 kv 19,9 kva para raio Bom acesso bom.fazenda Santa Tereza - UC 3165559-0 cliente: Persio de Freitas Vilela. RDR Arapoema | AD30: trafo queimado 5702259004 queimado 15 kv 19,9 kva para raio Bom acesso bom. fazenda Santa Tereza - UC 3165559-0 cliente: Persio de Freitas Vilela. RDR Arapoema
A31: ETO-RD-AR 00504/2026 | B31: mar | C31: Sem interrupção comprovada | D31: Sem interrupção | E31: EXPURGO | F31: QUEIMADO | G31: esteira 1.582 | H31: AUSENTE DA CRÍTICA | I31: 5752570159 | J31: ENC-MLAR05 000157/2026 | K31: 612600330 | L31: 2026-03-17 20:04 | M31: 2026-03-18 21:24 | N31: FORMS SUBST DE TRANSFORMADOR | O31: ETO-RD-AR | P31: MURICILANDIA | Q31: QUEIMADO | R31: DESCARGA ATMOSFÉRICA | S31: 1298121 | T31: 586769 | U31: sim | V31: CAUSA NAO IDENTIFICADA | W31: CAUSA NAO IDENTIFICADA - ESPECIFICAR | Z31: SIM | AA31: leitura caso a caso | AB31: Fora do indicador: a Crítica nunca registrou defeito aberto neste transformador — em data nenhuma dos sete meses. O código aparece na base, mas só como interrompido ou manobrado, que é o que acontece com quem fica sem energia por defeito de outro equipamento. | AC31: 5752570159 30kva 34.5kv e para raioacesso livre | AD31: ETO-RD-AR 504/2026 TRAFO 5752570159 TRAFO RETIRADO POTÊNCIA : 30 KVA TENSÃO : 34.4 KV Nº ENERGISA (CITD) : 129196 Nº DE SÉRIE : 1298121 MARCA : ROMAGNOLE DATA FABRICAÇÃO : 06/2024 IMPEDANCIA : 3,69 POS. TAP : 4 TRAFO INSTALADO POTÊNCIA : 30 KVA TENSÃO : 34.5 KV Nº ENERGISA (CITD) : 147732 Nº DE SÉRIE : 586769 MARCA : ITAIPU DATA FABRICAÇÃO : 07/2025 IMPEDANCIA : 3,96 POS. TAP : 04 OBS: LANÇADO DISPONIBILIDADE REFERENTE AO DESLOCAMENTO DA SS ETO-RD-AG 224/2026 PARA FAZER MELHORIA,PORÉM NÃO FOI PRECISO DEVIDO NÃO TER TRAFO NO LOCAL.
A32: ETO-RD-AR 00468/2026 | B32: mar | C32: Sem interrupção comprovada | D32: Sem interrupção | E32: EXPURGO | F32: QUEIMADO | G32: esteira 1.582 | H32: AUSENTE DA CRÍTICA | I32: 5301889004 | J32: ENC-MLAR01 000136/2026 | K32: 612600312 | L32: 2026-03-12 19:30 | M32: 2026-03-13 15:30 | N32: FORMS SUBST DE TRANSFORMADOR | O32: ETO-RD-AR | P32: ARAGUAINA | Q32: QUEIMADO | R32: BUCHA DANIFICADA | S32: 141362 | T32: 826192 | U32: sim | Z32: não | AA32: leitura caso a caso | AB32: Fora do indicador: o dono reviu a própria decisão: “se estiver fora daquelas janelas … deverão ser excluídos”. Ele havia mandado incluir por ler queima com SIGCO incorreto; conferido na Crítica crua, o código 5301889004 não aparece em papel nenhum nos sete meses — nem com defeito, nem interrompido, nem manobrado. Nem o 5701889004 que a OS escreve, nem o 570188904 que a SS escreve. Sem registro de interrupção não há evento a medir. | AC32: Trafo 570188904 queimado 15kvaAcesso: Somente caminhonetePara-raio; Queimado Equipe: 004op26 | AD32: ETO-RD-AR 468/2026 TRAFO 5701889004 TRAFO RETIRADO POTÊNCIA : 15 KVA TENSÃO : 13.8 KV Nº ENERGISA (CITD) : 7658 Nº DE SÉRIE : 141362 MARCA : ITB DATA FABRICAÇÃO : 07/9 IMPEDANCIA : 2,43 POS. TAP : 03 TRAFO INSTALADO POTÊNCIA : 15 KVA TENSÃO : 13.8 KV Nº ENERGISA (CITD) : 149974 Nº DE SÉRIE : 826192 MARCA : TRAEL DATA FABRICAÇÃO : 01/2026 IMPEDANCIA : 2,5 POS. TAP : 05
A33: ETO-RD-AR 00437/2026 | B33: mar | C33: Sem interrupção comprovada | D33: Sem interrupção | E33: EXPURGO | F33: QUEIMADO | G33: esteira 1.582 | H33: AUSENTE DA CRÍTICA | I33: 5701771022 | J33: ENC-MLAR03 000007/2026 | K33: 612600271 | L33: 2026-03-07 13:00 | M33: 2026-03-08 13:40 | N33: FORMS SUBST DE TRANSFORMADOR | O33: ETO-RD-AR | P33: BABACULANDIA | Q33: QUEIMADO | R33: DESCARGA ATMOSFÉRICA | S33: 1611007 | T33: 827838 | U33: sim | Z33: SIM | AA33: leitura caso a caso | AB33: Fora do indicador: o ativo não existe na base de interrupção. Sem registro de interrupção não há evento a medir. | AC33: Trafo 5701771022 queimado 15kvaTensão: 34.5Acesso; somente para caminhonteEquipe: 004op27Endereço: Chacara Bela Vista | AD33: ETO-RD-AR 437/2026 TRAFO 5701771022 TRAFO RETIRADO POTÊNCIA : 15 KVA TENSÃO : 34.5 KV Nº ENERGISA (CITD) : 142471 Nº DE SÉRIE : 1611007 MARCA : ITB DATA FABRICAÇÃO : 05/2024 IMPEDANCIA : 2,88 POS. TAP : 05 TRAFO INSTALADO POTÊNCIA : 15 KVA TENSÃO : 34.5 KV Nº ENERGISA (CITD) : 150115 Nº DE SÉRIE : 827838 MARCA : TRAEL DATA FABRICAÇÃO : 02/2026 IMPEDANCIA : 3,0 POS. TAP : 03
A34: DOLP-RD-PA 00003/2026 | B34: jan | C34: Sem interrupção comprovada | D34: Sem interrupção | E34: EXPURGO | F34: QUEIMADO | G34: esteira 1.582 | H34: AUSENTE DA CRÍTICA | I34: 5700121151 | J34: DLP-CTPA01 000001/2026 | K34: 112600438 | L34: 2026-01-02 15:28 | M34: 2026-01-03 17:32 | N34: FORMS SUBST DE TRANSFORMADOR | O34: DOLP-RD-PA | P34: SANTA TEREZA DO TOCANTINS | Q34: QUEIMADO | R34: NÃO IDENTIFICADO | S34: 185859 | T34: 454942 | U34: sim | Z34: SIM | AA34: leitura caso a caso | AB34: Fora do indicador: o ativo não existe na base de interrupção. Sem registro de interrupção não há evento a medir. | AC34: segue ss de 01 trafo de 30 kvar e 03 para raio queimado da rede de 34,500kv para ser subistituido pela equipe de manutencão acesso bom cliente penalizado 01 equipe que atendeu 151op01 cel, 63992629128/984188058 favor agilizar o atendimento devido cliente informar que está com 03 dias sem energia | AD34: MEDIDO_ EMERGENCIAL_ Msegue ss de 01 trafo de 30 kvar e 03 para raio queimado da rede de 34,500kv para ser subistituido pela equipe de manutencão acesso bom cliente penalizado 01 equipe que atendeu 151op01 cel, 63992629128/984188058 favor agilizar o atendimento devido cliente informar que está com 03 dias sem energia EQUIPE: 833007 ENCARREGADO: JOSE AILTON NO TRAFO [5700121151]
A35: ETO-RD-AR 00434/2026 | B35: mar | C35: Sem interrupção comprovada | D35: Sem interrupção | E35: EXPURGO | F35: QUEIMADO | G35: esteira 1.582 | H35: AUSENTE DA CRÍTICA | I35: 5710028040 | J35: ENC-MLAR01 000130/2026 | K35: 612600266 | L35: 2026-03-06 22:17 | M35: 2026-03-07 16:30 | N35: FORMS SUBST DE TRANSFORMADOR | O35: ETO-RD-AR | P35: ARAGOMINAS | Q35: QUEIMADO | R35: DESCARGA ATMOSFÉRICA | S35: 388798 | T35: 974078 | U35: sim | V35: MEIO AMBIENTE | W35: DESCARGA ATMOSFERICA | Z35: SIM | AA35: leitura caso a caso | AB35: Fora do indicador: a Crítica nunca registrou defeito aberto neste transformador — em data nenhuma dos sete meses. O código aparece na base, mas só como interrompido ou manobrado, que é o que acontece com quem fica sem energia por defeito de outro equipamento. | AC35: Trafo 5710028040 Queimado Potencia:15 KVATensão: 13,8 KVPara raio: Queimado Acesso: CamionetaEquipe: 040op36 (63)992870450 | AD35: ETO-RD-AR 434/2026 TRAFO 5710028040 TRAFO RETIRADO POTÊNCIA :15 KVA TENSÃO : 13.8 KV Nº ENERGISA (CITD) : 05100990 Nº DE SÉRIE : 388798 MARCA : TRAEL DATA FABRICAÇÃO : 06/2016 IMPEDANCIA : 2,4 POS. TAP : 04 TRAFO INSTALADO POTÊNCIA : 15 KVA TENSÃO : 13.8 KV Nº ENERGISA (CITD) : 148906 Nº DE SÉRIE : 974078 MARCA : ITB DATA FABRICAÇÃO : 2015 IMPEDANCIA : 2,38 POS. TAP : 05
A36: ENC-RD-PS 00024/2026 | B36: jan | C36: Sem interrupção comprovada | D36: Sem interrupção | E36: EXPURGO | F36: QUEIMADO | G36: esteira 1.582 | H36: AUSENTE DA CRÍTICA | I36: 5700559233 | J36: ENC-LMPS01 000011/2026 | K36: 212600049 | L36: 2026-01-06 18:36 | M36: 2026-01-07 18:56 | N36: FORMS SUBST DE TRANSFORMADOR | O36: ENC-RD-PS | P36: ABREULANDIA | Q36: QUEIMADO | R36: DESCARGA ATMOSFÉRICA | S36: 525292 | U36: não | Z36: SIM | AA36: leitura caso a caso | AB36: Fora do indicador: o ativo não existe na base de interrupção. Sem registro de interrupção não há evento a medir. | AC36: segue SS ´para tratativa com equipe de manutençao subtituir trafo 5700559233 na rdr de abreulandia | AD36: SS ENC-RD-PS 24/2026 trafo 5700559233 TRAFO RETIRADO POTÊNCIA : 15KVA TENSÃO : 34.5KV Nº ENERGISA (CITD) : 122431 Nº DE SÉRIE : 525292 MARCA : TRAEL DATA FABRICAÇÃO : 01/2020 IMPEDANCIA : 2,91 POS. TAP : 03 TRAFO INSTALADO' POTÊNCIA : 25KVA TENSÃO : 34.5KV Nº ENERGISA (CITD) : 144285 Nº DE SÉRIE : Z 260816 MARCA : ITAM DATA FABRICAÇÃO : 12/2024 IMPEDANCIA : 3.15 POS. TAP : 03
A37: ENC-RD-PS 00044/2026 | B37: jan | C37: Sem interrupção comprovada | D37: Sem interrupção | E37: EXPURGO | F37: QUEIMADO | G37: esteira 1.582 | H37: AUSENTE DA CRÍTICA | I37: 5710028046 | J37: ENC-LMPS04 000011/2026 | K37: 212600073 | L37: 2026-01-11 10:38 | M37: 2026-01-12 16:02 | N37: FORMS SUBST DE TRANSFORMADOR | O37: ENC-RD-PS | P37: NOVA ROSALANDIA | Q37: QUEIMADO | R37: DESCARGA ATMOSFÉRICA | S37: 69095 | U37: não | Z37: SIM | AA37: leitura caso a caso | AB37: Fora do indicador: o ativo não existe na base de interrupção. Sem registro de interrupção não há evento a medir. | AC37: TR 571002804610KVA13800PARA RAIO DANIFICADO ACESSO PARA CAMINHONETE (1)UC PENALIZADA EM CAMPO 046OP01 VILSON | AD37: SS ENC-RD-PS 44/2026 TR 5710028046 TRAFO RETIRADO POTÊNCIA : 10KVA TENSÃO : 13.8KV Nº ENERGISA (CITD) : ILEGIVEL Nº DE SÉRIE :69095 MARCA : TRAEL DATA FABRICAÇÃO : 11/2005 IMPEDANCIA : 2.52 POS. TAP : 01 TRAFO INSTALADO' POTÊNCIA : 15KVA TENSÃO : 34.5KV Nº ENERGISA (CITD) : 137057 Nº DE SÉRIE : C237007 MARCA : ITAM DATA FABRICAÇÃO : 2023 IMPEDANCIA : 2.41 POS. TAP : 03
A38: ENC-RD-PS 00054/2026 | B38: jan | C38: Sem interrupção comprovada | D38: Sem interrupção | E38: EXPURGO | F38: QUEIMADO | G38: esteira 1.582 | H38: AUSENTE DA CRÍTICA | I38: 5701203084 | J38: ENC-LMPS04 000013/2026 | K38: 212600080 | L38: 2026-01-12 13:21 | M38: 2026-01-14 16:40 | N38: FORMS SUBST DE TRANSFORMADOR | O38: ENC-RD-PS | P38: DIVINOPOLIS DO TOCANTINS | Q38: QUEIMADO | R38: DESCARGA ATMOSFÉRICA | S38: 451481 | T38: 290390 | U38: sim | Z38: SIM | AA38: leitura caso a caso | AB38: Fora do indicador: a Crítica nunca registrou defeito aberto neste transformador — em data nenhuma dos sete meses. O código aparece na base, mas só como interrompido ou manobrado, que é o que acontece com quem fica sem energia por defeito de outro equipamento. | AC38: Segue ss para tratativa com equipe de manutençao o quanto antes susbtituir trafo 5701203084 queimado na rdr de divinopoles | AD38: SS ENC-RD-PS 54/2026 trafo 5701203084 TRAFO RETIRADO POTÊNCIA : 15KVA TENSÃO : 34.5KV Nº ENERGISA (CITD) : 06110358 Nº DE SÉRIE : 451481 MARCA : TRAEL DATA FABRICAÇÃO : 12/2017 IMPEDANCIA : 2.96 POS. TAP : 03 TRAFO INSTALADO' POTÊNCIA : 15KVA TENSÃO : 34.5KV Nº ENERGISA (CITD) : 149797 Nº DE SÉRIE : 290390 MARCA : ITAM DATA FABRICAÇÃO : 10/2025 IMPEDANCIA : 3.28 POS. TAP : 03
A39: ENC-RD-PS 00057/2026 | B39: jan | C39: Sem interrupção comprovada | D39: Sem interrupção | E39: EXPURGO | F39: QUEIMADO | G39: esteira 1.582 | H39: AUSENTE DA CRÍTICA | I39: 5710441149 | J39: ENC-LMPS04 000012/2026 | K39: 212600077 | L39: 2026-01-12 17:10 | M39: 2026-01-13 20:09 | N39: FORMS SUBST DE TRANSFORMADOR | O39: ENC-RD-PS | P39: CASEARA | Q39: QUEIMADO | R39: DESCARGA ATMOSFÉRICA | S39: 1568543 | T39: 586759 | U39: sim | Z39: SIM | AA39: leitura caso a caso | AB39: Fora do indicador: o ativo não existe na base de interrupção. Sem registro de interrupção não há evento a medir. | AC39: TR 571044114930KVAT 34500PARA RAIO DANIFICADO ACESSO PARA CAMINHAO (1) PENALIZADA WELVIS SUP. DIVINOPOLIS | AD39: SS ENC-RD-PS 57/2026 TRAFO: 5710428084 TRAFO RETIRADO POTÊNCIA : 30KVA TENSÃO : 34.5KV Nº ENERGISA (CITD) : 143090 Nº DE SÉRIE : 1568543 MARCA : ROMAGNOLE DATA FABRICAÇÃO : 11/2024 IMPEDANCIA : 4.86 POS. TAP : 02 TRAFO INSTALADO' POTÊNCIA : 30KVA TENSÃO : 34.5KV Nº ENERGISA (CITD) : 147722 Nº DE SÉRIE : 586759 MARCA : ITAIPU DATA FABRICAÇÃO : 07/2025 IMPEDANCIA : 3.98 POS. TAP : 02
A40: ETO-RD-AR 00001/2026 | B40: jan | C40: Sem interrupção comprovada | D40: Sem interrupção | E40: EXPURGO | F40: QUEIMADO | G40: esteira 1.582 | H40: AUSENTE DA CRÍTICA | I40: 5703016016 | J40: ENC-MLAR01 000013/2026 | K40: 612600021 | L40: 2026-01-02 10:17 | M40: 2026-01-02 18:00 | N40: FORMS SUBST DE TRANSFORMADOR | O40: ETO-RD-AR | P40: WANDERLANDIA | Q40: QUEIMADO | R40: SOBRECARGA | S40: 180489 | T40: 435142 | U40: sim | Z40: SIM | AA40: leitura caso a caso | AB40: Fora do indicador: o ativo não existe na base de interrupção. Sem registro de interrupção não há evento a medir. | AC40: SUBSTITUIR o Trafo 5703016016Lançar vão de rede de 100 metros , cabo AA / 4Instalar chave trafo ELO 0,5HAcesso livrePotencia de 15 kVA | AD40: ETO-RD-AR 01/2026 TRAFO RETIRADO POTÊNCIA : 15 KVA TENSÃO : 34.5 KV Nº ENERGISA (CITD) : ILEGIVEL Nº DE SÉRIE : 180489 MARCA : ABB DATA FABRICAÇÃO : 04/2002 IMPEDANCIA : 2,9 POS. TAP : 03 TRAFO INSTALADO POTÊNCIA : 15 KVA TENSÃO : 34.5 KV Nº ENERGISA (CITD) : 105598 Nº DE SÉRIE : 435142 MARCA : TRAEL DATA FABRICAÇÃO : 2017 IMPEDANCIA : 2,9 POS. TAP : 05
A41: ETO-RD-AG 00249/2026 | B41: mar | C41: Sem interrupção comprovada | D41: Sem interrupção | E41: EXPURGO | F41: QUEIMADO | G41: esteira 1.582 | H41: AUSENTE DA CRÍTICA | I41: 5700696045 | J41: ENC-MLAG01 000060/2026 | K41: 662600154 | L41: 2026-03-03 12:18 | M41: 2026-03-04 18:23 | N41: FORMS SUBST DE TRANSFORMADOR | O41: ETO-RD-AG | P41: AUGUSTINOPOLIS | Q41: QUEIMADO | R41: DESCARGA ATMOSFÉRICA | S41: 566197014 | T41: 183077 | U41: sim | V41: MEIO AMBIENTE | W41: DESCARGA ATMOSFERICA | Z41: SIM | AA41: leitura caso a caso | AB41: Fora do indicador: a Crítica nunca registrou defeito aberto neste transformador — em data nenhuma dos sete meses. O código aparece na base, mas só como interrompido ou manobrado, que é o que acontece com quem fica sem energia por defeito de outro equipamento. | AC41: TROCA DE TRAFO 5700696045 QUEIMADO DE 30KVA DA 34.5 PARA RAIOS QUEIMADO. ACESSO BOMTROCAR JOGO DE CHAVESUBSTITUIR OS GLV'SLEVAR ROLDANA DA BT. | AD41: TROCA DE TRAFO 5700696045 QUEIMADO DE 30KVA DA 34.5 PARA RAIOS QUEIMADO. ACESSO BOM TROCAR JOGO DE CHAVE SUBSTITUIR OS GLV'S LEVAR ROLDANA DA BT. TRAFO Nº 5700696045 TRAFO RETIRADO POTÊNCIA; 30KVA 34,5KV DATA DE FAB; 07/99 REF.; 11/2017 MARCA; SIEMENS - TRAEL Nº CITD; 108243 Nº SÉRIE; 566197014 POS. DO TAP; 2 IMPEDÂNCIA; 13,26 / 13,04 / 12,97 TRAFO INSTALADO POTÊNCIA; 30KVA 34,5KV DATA DE FAB; 12/01 REF.; 04/2024 MARCA; ABB - TRAEL PA Nº CITD; 138765 Nº SÉRIE; 183077 POS. DO TAP; 2 IMPEDÂNCIA;4,17 MEDIÇÃO; 13,26 / 13,04 /12,97 OBS; SUBST JOGO DE 03X CHAV
...

Sheet Detalhes2
A1: Detalhes do Contagem de SS - Motivo: Fora da janela, Categoria pelo texto: QUEIMADO
A3: SS | B3: Mês | C3: Macro categoria | D3: Motivo | E3: Resultado | F3: Categoria pelo texto | G3: Fonte da categoria | H3: Categoria da leitura | I3: Trafo | J3: OS | K3: Obra | L3: Abertura | M3: Término | N3: Tipo da SS | O3: Equipe | P3: Localidade | Q3: Origem da SS | R3: Defeito da SS | S3: NS retirado | T3: NS instalado | U3: Prova de troca | V3: Crítica — causa | W3: Crítica — subcausa | X3: TMAE — causa | Y3: TMAE — subcausa | Z3: No Infotrafo | AA3: Origem da leitura | AB3: Por que saiu | AC3: Texto da SS | AD3: Texto da OS
A4: DG-RD-PO 00064/2026 | B4: jan | C4: Sem interrupção comprovada | D4: Fora da janela | E4: EXPURGO | F4: QUEIMADO | G4: esteira 1.582 | H4: FORA DA JANELA DA CRÍTICA | I4: 5711513001 | J4: DG-MLPO01 000016/2026 | K4: 312600058 | L4: 2026-01-16 03:49 | M4: 2026-01-16 12:25 | N4: FORMS SUBST DE TRANSFORMADOR | O4: DG-RD-PO | P4: PORTO NACIONAL | Q4: AVARIADO | R4: NÃO IDENTIFICADO | S4: 47057 | T4: 1587612 | U4: sim | Z4: SIM | AA4: leitura caso a caso | AB4: Fora do indicador: a SS não cai na janela de nenhuma interrupção. | AC4: Segue nota para envia equipe manutenção substituir Trafo 5711513001 de 10kva e para-raio avariado, Tensão 7,9kv, Rural de Porto Nacional Assentamento P.A. Pau Darco, Chac. Duas Irmãs, Acesso para camionete 4x4.Obs. Informação da equipe 001OP11 Trafo não Funcionando. | AD4: medido_ emergencial_ substituição de trafo queimado rdr porto
A5: DOLP-RD-PA 00122/2026 | B5: jan | C5: Sem interrupção comprovada | D5: Fora da janela | E5: EXPURGO | F5: QUEIMADO | G5: esteira 1.582 | H5: FORA DA JANELA DA CRÍTICA | I5: 5710169006 | J5: DLP-MLPA01 000020/2026 | K5: 112600156 | L5: 2026-01-25 10:13 | M5: 2026-01-26 18:30 | N5: FORMS SUBST DE TRANSFORMADOR | O5: DOLP-RD-PA | P5: TOCANTINIA | Q5: QUEIMADO | R5: NÃO IDENTIFICADO | S5: 358539 | T5: 464890 | U5: sim | Z5: SIM | AA5: leitura caso a caso | AB5: Fora do indicador: a Crítica registra defeito aberto neste transformador, mas em data que não cabe na janela desta SS. | AC5: segue ss de 01 trafo de 15 kvar e 01 para raio queimado da rede de 34.500kv para ser subistituido pela equipe de manutencão cliente penalizado 01 equipe que atendeu 006op01 cel, 63992363662/992379486 acesso livre favor agilizar o atendimento | AD5: MEDIDO_ EMERGENCIAL_ segue ss de 01 trafo de 15 kvar e 01 para raio queimado da rede de 34.500kv para ser subistituido pela equipe de manutencão cliente penalizado 01 equipe que atendeu 006op01 cel, 63992363662/992379486 acesso livre favor agilizar o atendimento DADOS ATENDIMENTO EQUIPE: PALMA11M LIDER: EDUARDO DA SILVA SANTOS CONTATO: 63 9296-7129 DOLP-RD-PA 000122/2026 DATA ATENDIMENTO: 26/01/2026 Atenção! Não intervenha na rede sem autorização do COI (Centro de Operações Integradas)
