Workbook
Name DadosExternos_2: 'BASE GERAL'!$A$1:$AJ$1582

Sheet Exportar Planilha (2)
A1: NUMERO_SS | B1: NUMERO_OS | C1: NUM_OBRA | D1: Coluna1 | E1: TASKDESCRIPTION | F1: ORIGEM_SS | G1: DEFEITO_SS | H1: ORIGEM | I1: DEFEITO | J1: ESQUEMA | K1: ANO | L1: ALIMENTADOR | M1: NUM_TRAFO | N1: NUM_PROJETO_SIGCO | O1: CRITICIDADE_SS | P1: SITUACAO_SS | Q1: DATA_ABERTURA_SS | R1: DATA_TERMINO_SS | S1: DATA_LIMITE_SS | T1: DESCICAO_DO_ATIVO | U1: LOCALIDADE | V1: SOLICITANTE | W1: RURA_URBANO | X1: TIPOSS | Y1: DESCRIPTION | Z1: POTENCIA_INST | AA1: POTENCIA_RET | AB1: POT_RET | AC1: DATA_ATUALIZACAO
A2: ETO-RD-AR 00011/2026 | B2: ENC-MLAR01 000016/2026 | C2: 612600024 | E2: ETO-RD-AR 11/2026_x000D_ TRAFO RETIRADO_x000D_ POTÊNCIA : 5 KVA_x000D_ TENSÃO : 34.5 KV_x000D_ Nº ENERGISA (CITD) : ILEGIVEL_x000D_ Nº DE SÉRIE : 125062_x000D_ MARCA : VIJAI_x000D_ DATA FABRICAÇÃO : 08/2008_x000D_ IMPEDANCIA : 2,85_x000D_ POS. TAP : 05_x000D_ _x000D_ TRAFO INSTALADO_x000D_ POTÊNCIA : 15 KVA_x000D_ TENSÃO : 34.5 KV_x000D_ Nº ENERGISA (CITD) : 110729_x000D_ Nº DE SÉRIE : 455521_x000D_ MARCA : TRAEL_x000D_ DATA FABRICAÇÃO : 2016_x000D_ IMPEDANCIA : 3,04_x000D_ POS. TAP : 05_x000D_ | F2: QUEIMADO | G2: DESCARGA ATMOSFÉRICA | H2: QUEIMADO | I2: NÃO IDENTIFICADO | J2: MC - SUBSTITUIÇÃO DE TRANSFORMADOR | K2: 2026 | L2: LD03010004 | M2: 5700876040 | N2: 8385 | O2: EMERGENCIAL | P2: SS ATENDIDA | Q2: 46025.77 | R2: 46026.583 | S2: 46028.77 | T2: BLOCO TRANSFORMADOR DE DISTRIBUIÇÃO | U2: ARAGOMINAS | V2: GUILHERME BORGES DE OLIVEIRA | W2: RURAL | X2: FORMS SUBST DE TRANSFORMADOR | Y2: 5700876040 10 kva 34.5kv e para raioacesso livre | Z2: 15 | AA2: 5 | AB2: 10KVA | AC2: 46225.761
A3: ETO-RD-GU 00314/2026 | B3: DBM-MLDB06 000046/2026 | C3: 412600319 | E3: SUBSTITUIÇÃO DE TRANSFORMADOR NA RDR DE PARANA_x000D_ _x000D_ INT: 20264171148086_x000D_ _x000D_ SS: ETO-RD-GU 314/2026_x000D_ _x000D_ ESPECIFICAÇÕES DO TRANSFORMADOR_x000D_ _x000D_ TRANSFORMADOR INSTALADO: 15 KVA_x000D_ _x000D_ TRANSFORMADOR RETIRADO: 15 KVA_x000D_ _x000D_ MEDIÇÕES_x000D_ _x000D_ LOGO APÓS A TROCA _x000D_ _x000D_ VAN: 218_x000D_ _x000D_ OBS:SUBSTITUIÇÃO DE TRANSFORMADOR AUTORIZADA PELO DIONE._x000D_ | F3: QUEIMADO | G3: DESCARGA ATMOSFÉRICA | H3: QUEIMADO | I3: DESCARGA ATMOSFÉRICA | J3: MC - SUBSTITUIÇÃO DE TRANSFORMADOR | K3: 2026 | L3: LD01066094 | M3: 5700866021 | N3: 8812 | O3: EMERGENCIAL | P3: SS ATENDIDA | Q3: 46091.577 | R3: 46092.754 | S3: 46094.577 | T3: BLOCO TRANSFORMADOR DE DISTRIBUIÇÃO | U3: PARANA | V3: JURANDY GOMES DE OLIVEIRA | W3: RURAL | X3: FORMS SUBST DE TRANSFORMADOR | Y3: Trafo 5700866021 queimado em campo de 15 kva tensão 19.9 kv acesso camionete para raio queimado,rdr de paranã | Z3: 15 | AA3: 15 | AB3: 15 | AC3: 46225.761
A4: ETO-RD-GR 00085/2026 | B4: ENC-MLGR03 000035/2026 | C4: 712600065 | E4: SUBSTITUIÇÃO DE TRAFO 5700632104, ETO-RD-GR 85/2026, FAZ. CHUPE RDR DE SANTA MARIA _x000D_ _x000D_ TRAFO RETIRADO_x000D_ POTÊNCIA : 15KVA _x000D_ TENSÃO : 34,5KV_x000D_ Nº ENERGISA (CITD) : 108759_x000D_ Nº DE SÉRIE : 442904_x000D_ MARCA : TRAEL_x000D_ DATA FABRICAÇÃO : 09/2017_x000D_ IMPEDANCIA : 3,06_x000D_ POS. TAP : 03_x000D_ _x000D_ TRAFO INSTALADO_x000D_ POTÊNCIA : 15KVA_x000D_ TENSÃO : 34,5KV_x000D_ Nº ENERGISA (CITD) : 149266_x000D_ Nº DE SÉRIE : 820252_x000D_ MARCA : TRAEL_x000D_ DATA FABRICAÇÃO : 11/2025_x000D_ IMPEDANCIA : 3,0_x000D_ POS. TAP : 3_x000D_ _x000D_ MEDIÇÃO 1: 00,18_x000D_ MEDIÇÃO 2: 00,08_x000D_ MEDIÇÃO 3: 00,07_x000D_ _x000D_ COORD._x000D_ X: 855817_x000D_ Y: 9019527 | F4: QUEIMADO | G4: DESCARGA ATMOSFÉRICA | H4: QUEIMADO | I4: DESCARGA ATMOSFÉRICA | J4: MC - SUBSTITUIÇÃO DE TRANSFORMADOR | K4: 2026 | L4: LD01065015 | M4: 5700632104 | N4: 8812 | O4: PROGRAMAVEL | P4: SS ATENDIDA | Q4: 46038.504 | R4: 46038.875 | S4: 46438.504 | T4: BLOCO TRANSFORMADOR DE DISTRIBUIÇÃO | U4: SANTA MARIA DO TOCANTINS | V4: VALERIA DE JESUS BORGES CARVAL | W4: RURAL | X4: FORMS SUBST DE TRANSFORMADOR | Y4: TRAFO QUEIMADO 5700632104 - 15KVA 19,9KV ACESSO LIVRE PARA RAIO QUEIMADO IND FAZENDA CHUPE - CLIENTE LENIEL FONSECA LOPES - UC 10074720 - TEL. 63984232073RDR SANTA MARIA | Z4: 15 | AA4: 15 | AB4: 15KVA | AC4: 46225.761
A5: ETO-RD-GU 00404/2026 | B5: DBM-MLDB05 000078/2026 | C5: 412600346 | E5: SUBSTITUIÇÃO DE TRANSFORMADOR NA RDR DE PEIXE_x000D_ _x000D_ INT: 20264210037659_x000D_ _x000D_ SS: ETO-RD-GU 404/2026_x000D_ _x000D_ ESPECIFICAÇÕES DO TRANSFORMADOR_x000D_ _x000D_ TRANSFORMADOR INSTALADO: 15KVA_x000D_ _x000D_ TRANSFORMADOR RETIRADO: 15KVA_x000D_ _x000D_ MEDIÇÕES_x000D_ _x000D_ LOGO APÓS A TROCA _x000D_ _x000D_ VAN: 220.8_x000D_ _x000D_ VBN: 220.8_x000D_ _x000D_ OBS:SUBSTITUIÇÃO DE TRANSFORMADOR AUTORIZADA PELO DIONE._x000D_ _x000D_ _x000D_ | F5: QUEIMADO | G5: NÃO IDENTIFICADO | H5: QUEIMADO | I5: NÃO IDENTIFICADO | J5: MC - SUBSTITUIÇÃO DE TRANSFORMADOR | K5: 2026 | L5: LD02072001 | M5: 5700924094 | N5: 8812 | O5: EMERGENCIAL | P5: SS ATENDIDA | Q5: 46110.794 | R5: 46112.36 | S5: 46113.794 | T5: BLOCO TRANSFORMADOR DE DISTRIBUIÇÃO | U5: PEIXE | V5: Wilmar Lucas Rodrigues Noleto | W5: RURAL | X5: FORMS SUBST DE TRANSFORMADOR | Y5: SEGUE SS DE TRAFO QUEIMADO NA RDR DE PEIXE, TRAFO DE 15KVA NA REDE DE 19.9KV, ACESSO LIVRE E PARA RAIOS QUEIMADO. | Z5: 15 | AA5: 15 | AB5: 15KVA | AC5: 46225.761
A6: ETO-RD-GU 00141/2026 | B6: DBM-MLDB03 000026/2026 | C6: 412600152 | E6: SUBSTITUIÇÃO DE TRANSFORMADOR NA RDR DE PEIXE_x000D_ _x000D_ INT: 20264106374261_x000D_ _x000D_ SS: ETO-RD-GU 141/2026_x000D_ _x000D_ ESPECIFICAÇÕES DO TRANSFORMADOR_x000D_ _x000D_ TRANSFORMADOR INSTALADO: 15 KVA_x000D_ _x000D_ TRANSFORMADOR RETIRADO: 05 KVA _x000D_ _x000D_ _x000D_ OBS:SUBSTITUIÇÃO DE TRANSFORMADOR AUTORIZADA PELO DIONE._x000D_ | F6: QUEIMADO | G6: DESCARGA ATMOSFÉRICA | H6: QUEIMADO | I6: DESCARGA ATMOSFÉRICA | J6: MC - SUBSTITUIÇÃO DE TRANSFORMADOR | K6: 2026 | L6: LD01066094 | M6: 5701125094 | N6: 8385 | O6: EMERGENCIAL | P6: SS ATENDIDA | Q6: 46051.638 | R6: 46052.995 | S6: 46054.638 | T6: BLOCO TRANSFORMADOR DE DISTRIBUIÇÃO | U6: PEIXE | V6: JURANDY GOMES DE OLIVEIRA | W6: RURAL | X6: FORMS SUBST DE TRANSFORMADOR | Y6: trafo 5701125094 de 15 kva queimado acesso livre rdr de peixe tensão 19.9 para raio queimado | Z6: 15 | AA6: 5 | AB6: 10 | AC6: 46225.761
A7: ETO-RD-AR 00414/2026 | B7: ENC-MLAR01 000123/2026 | C7: 612600256 | E7: ETO-RD-AR 414/2026_x000D_ TRAFO RETIRADO_x000D_ POTÊNCIA : 5 KVA_x000D_ TENSÃO : 34.5 KV_x000D_ Nº ENERGISA (CITD) : 35539_x000D_ Nº DE SÉRIE : 612733_x000D_ MARCA : ITB_x000D_ DATA FABRICAÇÃO : 08/2009_x000D_ IMPEDANCIA : 3,04_x000D_ POS. TAP : 05_x000D_ _x000D_ TRAFO INSTALADO_x000D_ POTÊNCIA : 15 KVA_x000D_ TENSÃO : 34.5 KV_x000D_ Nº ENERGISA (CITD) : 150083_x000D_ Nº DE SÉRIE : 827806_x000D_ MARCA : TRAEL_x000D_ DATA FABRICAÇÃO : 02/2026_x000D_ IMPEDANCIA : 3,0_x000D_ POS. TAP : 05_x000D_ | F7: QUEIMADO | G7: NÃO IDENTIFICADO | H7: QUEIMADO | I7: DESCARGA ATMOSFÉRICA | J7: MC - SUBSTITUIÇÃO DE TRANSFORMADOR | K7: 2026 | L7: LD02010004 | M7: 5700498080 | N7: 8812 | O7: EMERGENCIAL | P7: SS ATENDIDA | Q7: 46084.617 | R7: 46084.972 | S7: 46087.617 | T7: BLOCO TRANSFORMADOR DE DISTRIBUIÇÃO | U7: DARCINOPOLIS | V7: LEANDRO BISPO DE BARROS | W7: RURAL | X7: FORMS SUBST DE TRANSFORMADOR | Y7: trafo 5700498080 queimado 5 KVA acesso livre equipe 016op02 992153859 | Z7: 15 | AA7: 15 | AB7: 5kva | AC7: 46225.761
A8: DOLP-RD-PA 00374/2026 | B8: DLP-MPPA01 000088/2026 | C8: 112600369 | E8: MEDIDO__x000D_ _x000D_ EMERGENCIAL__x000D_ _x000D_ segue ss de 01 trafo de 45 kvar da rede de 34.500kv queimado para ser subistituido pela equipe de manutencão acesso livre clientes penalizado 01 equipe que fez o atendimento 092op01 cel, 63991002294/992607968 acesso livre favor agilizar o atendimento_x000D_ _x000D_ DADOS DO ATENDIMENTO:_x000D_ _x000D_ EQUIPE: 833017 - DLP-MPPA02_x000D_ ENCARREGADO: JULIO IGNACIO_x000D_ DATA: 23/03/2026 | F8: QUEIMADO | G8: NÃO IDENTIFICADO | H8: QUEIMADO | I8: NÃO IDENTIFICADO | J8: MC - SUBSTITUIÇÃO DE TRANSFORMADOR | K8: 2026 | L8: LD01059122 | M8: 5730634070 | N8: 8812 | O8: EMERGENCIAL | P8: SS ATENDIDA | Q8: 46103.837 | R8: 46104.75 | S8: 46106.837 | T8: BLOCO TRANSFORMADOR DE DISTRIBUIÇÃO | U8: RIO SONO | V8: JOAO PAULO VASCONCELOS MARINHO | W8: RURAL | X8: FORMS SUBST DE TRANSFORMADOR | Y8: segue ss de 01 trafo de 45 kvar da rede de 34.500kv queimado para ser subistituido pela equipe de manutencão acesso livre clientes penalizado 01 equipe que fez o atendimento 092op01 cel, 63991002294/992607968 acesso livre favor agilizar o atendimento | Z8: 45 | AA8: 45 | AB8: 45 kvar | AC8: 46225.761
A9: ETO-RD-AR 00207/2026 | B9: ENC-MLAR05 000089/2026 | C9: 612600141 | E9: ETO-RD-AR 207/2026_x000D_ TR: 5366985025_x000D_ _x000D_ TRAFO RETIRADO_x000D_ POTÊNCIA : 15KVA_x000D_ TENSÃO : 34,5KV_x000D_ Nº ENERGISA (CITD) : 148084_x000D_ Nº DE SÉRIE : C287221_x000D_ MARCA : ITAM_x000D_ DATA FABRICAÇÃO : 08/2025_x000D_ IMPEDANCIA : 3,13_x000D_ POS. TAP : 03_x000D_ _x000D_ TRAFO INSTALADO_x000D_ POTÊNCIA : 15KVA_x000D_ TENSÃO : 34,5KV_x000D_ Nº ENERGISA (CITD) : 149294_x000D_ Nº DE SÉRIE : 820280_x000D_ MARCA : TRAEL_x000D_ DATA FABRICAÇÃO : 11/2025_x000D_ IMPEDANCIA : 3,0_x000D_ POS. TAP : 03_x000D_ | F9: QUEIMADO | G9: DESCARGA ATMOSFÉRICA | H9: QUEIMADO | I9: DESCARGA ATMOSFÉRICA | J9: MC - SUBSTITUIÇÃO DE TRANSFORMADOR | K9: 2026 | L9: LD02010153 | M9: 5366985025 | N9: 8812 | O9: EMERGENCIAL | P9: SS ATENDIDA | Q9: 46055.572 | R9: 46055.75 | S9: 46058.572 | T9: BLOCO TRANSFORMADOR DE DISTRIBUIÇÃO | U9: ARAPOEMA | V9: MAIKOM DOUGLAS DA SILVA | W9: RURAL | X9: FORMS SUBST DE TRANSFORMADOR | Y9: Boa noite,Favor enviar manutenção para subsitutir trafo 5366985025 | Z9: 15 | AA9: 15 | AB9: 15 | AC9: 46225.761
A10: DOLP-RD-PA 00429/2026 | B10: DLP-CTPA00 000064/2026 | C10: 112600384 | E10: MEDIDO__x000D_ _x000D_ 01. Baixado para consumo de material_x000D_ _x000D_ Transformador com vazamento de oleo grande proporção 5764409122 feito divisão de circuito recente com 5700354122, potencia 112kva, tensão 13.8, acesso livre a caminhao, para raio bom._x000D_ _x000D_ DADOS DO ATENDIMENTO:_x000D_ DOLP-RD-PA 429/2026_x000D_ EQUIPE: 833019 - DOLP-CT-PA 07_x000D_ ENCARREGADO: REGINALDO DE OLIVEIRA_x000D_ DATA: 08/04/2026 | F10: AVARIADO | G10: VAZAMENTO DE ÓLEO | H10: AVARIADO | I10: VAZAMENTO DE ÓLEO | J10: MC - SUBSTITUIÇÃO DE TRANSFORMADOR | K10: 2026 | L10: AL03059122 | M10: 5700354122 | N10: 25962 | O10: EMERGENCIAL | P10: SS ATENDIDA | Q10: 46120.616 | R10: 46120.75 | S10: 46123.616 | T10: TRANSFORMADOR DE DISTRIBUIÇÃO ENERGISA 13.8Kv | U10: PALMAS | V10: HELDER SILVA CARVALHO | W10: URBANO | X10: FORMS SUBST DE TRANSFORMADOR | Y10: Transformador com vazamento de oleo grande proporção 5764409122 feito divisão de circuito recente com 5700354122, potencia 112kva, tensão 13.8, acesso livre a caminhao, para raio bom. | Z10: 10 | AA10: 10 | AB10: 112,5 | AC10: 46225.761
A11: ETO-RD-GU 00105/2026 | B11: DBM-MLDB05 000017/2026 | C11: 412600144 | E11: SUBSTITUIÇÃO DE TRANSFORMADOR NA RDR DE ARAGUAÇU_x000D_ _x000D_ INT: S/N_x000D_ _x000D_ SS: ETO-RD-GU 105/2026_x000D_ _x000D_ ESPECIFICAÇÕES DO TRANSFORMADOR_x000D_ _x000D_ TRANSFORMADOR INSTALADO: 15KVA_x000D_ _x000D_ TRANSFORMADOR RETIRADO: 15KVA_x000D_ _x000D_ MEDIÇÕES_x000D_ _x000D_ LOGO APÓS A TROCA _x000D_ _x000D_ VAN: 210.3_x000D_ _x000D_ VBN: 210.3_x000D_ _x000D_ VAB: 419_x000D_ _x000D_ OBS:SUBSTITUIÇÃO DE TRANSFORMADOR AUTORIZADA PELO DIONE._x000D_ _x000D_ | F11: QUEIMADO | G11: DESCARGA ATMOSFÉRICA | H11: QUEIMADO | I11: DESCARGA ATMOSFÉRICA | J11: MC - SUBSTITUIÇÃO DE TRANSFORMADOR | K11: 2026 | L11: LD01003036 | M11: 5710170032 | N11: 8812 | O11: EMERGENCIAL | P11: SS ATENDIDA | Q11: 46041.749 | R11: 46043.565 | S11: 46044.749 | T11: BLOCO TRANSFORMADOR DE DISTRIBUIÇÃO | U11: ARAGUACU | V11: JONATAN ALVES DE SOUZA | W11: RURAL | X11: FORMS SUBST DE TRANSFORMADOR | Y11: SEGUE SOLICITAÇÃO DE SERVIÇO PARA TROCA DE TRAFO QUEIMADO | Z11: 15 | AA11: 15 | AB11: 15KVA | AC11: 46225.761
A12: ETO-RD-AR 00613/2026 | B12: ENC-MLAR03 000041/2026 | C12: 612600369 | E12: ETO-RD-AR 613/2026_x000D_ TRAFO 5702072004_x000D_ TRAFO RETIRADO_x000D_ POTÊNCIA : 15 KVA_x000D_ TENSÃO : 13.8 KV_x000D_ Nº ENERGISA (CITD) : ILEGIVEL_x000D_ Nº DE SÉRIE : 141321_x000D_ MARCA : ITB_x000D_ DATA FABRICAÇÃO : 07/99_x000D_ IMPEDANCIA : 2,45_x000D_ POS. TAP : 05_x000D_ _x000D_ TRAFO INSTALADO_x000D_ POTÊNCIA : 15 KVA_x000D_ TENSÃO : 13.8 KV_x000D_ Nº ENERGISA (CITD) : 150022_x000D_ Nº DE SÉRIE : 827745_x000D_ MARCA : TRAEL_x000D_ DATA FABRICAÇÃO : 02/2026_x000D_ IMPEDANCIA : 2,5_x000D_ POS. TAP : 05_x000D_ | F12: QUEIMADO | G12: DESCARGA ATMOSFÉRICA | H12: QUEIMADO | I12: DESCARGA ATMOSFÉRICA | J12: MC - SUBSTITUIÇÃO DE TRANSFORMADOR | K12: 2026 | L12: AL04096004 | M12: 5702072004 | N12: 8812 | O12: EMERGENCIAL | P12: SS ATENDIDA | Q12: 46115.853 | R12: 46116.451 | S12: 46118.853 | T12: BLOCO TRANSFORMADOR DE DISTRIBUIÇÃO | U12: ARAGUAINA | V12: SIRDEIS ALVES MONTEIRO | W12: RURAL | X12: FORMS SUBST DE TRANSFORMADOR | Y12: trafo 5702072004 queimado | Z12: 15 | AA12: 15 | AB12: 15 kva | AC12: 46225.761
A13: ETO-RD-AR 00551/2026 | B13: ENC-MLAR01 000152/2026 | C13: 612600337 | E13: ETO-RD-AR 551/2026_x000D_ TRAFO 5700322060_x000D_ TRAFO RETIRADO_x000D_ POTÊNCIA : 15 KVA_x000D_ TENSÃO : 13.8 KV_x000D_ Nº ENERGISA (CITD) : P8322_x000D_ Nº DE SÉRIE : 178008_x000D_ MARCA : ABB_x000D_ DATA FABRICAÇÃO : 02/2001_x000D_ IMPEDANCIA : 2,36_x000D_ POS. TAP : 03_x000D_ _x000D_ TRAFO INSTALADO_x000D_ POTÊNCIA : 15 KVA_x000D_ TENSÃO : 13.8 KV_x000D_ Nº ENERGISA (CITD) : 149855_x000D_ Nº DE SÉRIE : C297819_x000D_ MARCA : ITAM_x000D_ DATA FABRICAÇÃO : 12/2025_x000D_ IMPEDANCIA : 2,61_x000D_ POS. TAP : 05_x000D_ | F13: QUEIMADO | G13: NÃO IDENTIFICADO | H13: QUEIMADO | I13: DESCARGA ATMOSFÉRICA | J13: MC - SUBSTITUIÇÃO DE TRANSFORMADOR | K13: 2026 | L13: AL01054060 | M13: 5700322060 | N13: 8812 | O13: EMERGENCIAL | P13: SS ATENDIDA | Q13: 46105.727 | R13: 46106.507 | S13: 46108.727 | T13: BLOCO TRANSFORMADOR DE DISTRIBUIÇÃO | U13: NOVA OLINDA | V13: Wilmar Lucas Rodrigues Noleto | W13: RURAL | X13: FORMS SUBST DE TRANSFORMADOR | Y13: SEGUE SS DE TRAFO QUEIMADO NA RDR DE NOVA OLINDA, TRAFO DE 15KVA NA REDE DE 7.8KV, PARA RAIO QUEIMADO E ACESSO LIVRE. | Z13: 15 | AA13: 15 | AB13: 15KVA | AC13: 46225.761
... A17: ETO-RD-GU 00042/2026 | B17: ETO-RD-GU 000114/2026 | C17: 412600082 | E17: SS: ETO-RD-GU 42/2026_x000D_ _x000D_ FOI FEITO COM EQUIPE PROPRIA ENERGISA_x000D_ _x000D_ FOI FEITO A SUBTITUIÇÃO DE TRANSFORMADOR DE 15KVA POR 15KVA | F17: QUEIMADO | G17: NÃO IDENTIFICADO | H17: QUEIMADO | I17: SOBRECARGA | J17: MC - SUBSTITUIÇÃO DE TRANSFORMADOR | K17: 2026 | L17: LD01066094 | M17: 5701136094 | N17: 8812 | O17: EMERGENCIAL | P17: SS ATENDIDA | Q17: 46032.857 | R17: 46033.526 | S17: 46035.857 | T17: BLOCO TRANSFORMADOR DE DISTRIBUIÇÃO | U17: PEIXE | V17: Wilmar Lucas Rodrigues Noleto | W17: RURAL | X17: FORMS SUBST DE TRANSFORMADOR | Y17: SEGUE SS DE TRAFO QUEIMADO NA RDR DE SAO VALERIO, TRAFO DE 15KVA NA REDE DE 19KV, ACESSO LIVRE PARA CAMINHONTE, PARA RAIO QUEIMADO. | Z17: 15 | AA17: 15 | AB17: 15KVA | AC17: 46225.761
A18: ETO-RD-AR 00522/2026 | B18: ETO-RD-AR 000767/2026 | C18: 612600331 | E18: TR 5700117063_x000D_ 15KVA_x000D_ QUEIMADO _x000D_ PARA RAIO NOVO _x000D_ ACESSO LIVRE_x000D_ _x000D_ _x000D_ 060OP01 ESTEVE NO LOCAL | F18: QUEIMADO | G18: DESCARGA ATMOSFÉRICA | H18: QUEIMADO | I18: DESCARGA ATMOSFÉRICA | J18: MC - FERRAGENS | K18: 2026 | L18: LD01054060 | M18: 5700117063 | N18: 8812 | O18: EMERGENCIAL | P18: SS ATENDIDA | Q18: 46100.669 | R18: 46101.755 | S18: 46103.669 | T18: BLOCO TRANSFORMADOR DE DISTRIBUIÇÃO | U18: PAU D'ARCO | V18: Felipe Batista Ferrreira | W18: RURAL | X18: FORMS SUBST DE TRANSFORMADOR | Y18: TR 570011706315KVAQUEIMADO PARA RAIO NOVO ACESSO LIVRE060OP01 ESTEVE NO LOCAL | AB18: 15KVA | AC18: 46225.761
A19: ETO-RD-GR 00034/2026 | B19: ENC-MLGR01 000016/2026 | C19: 712600042 | E19: SUBSTITUIÇÃO DE TRAFO 5700026195 ETO-RD-GR 34/2026 AST. P.A RIO VERMELHO RDR DE CENTENARIO _x000D_ _x000D_ TRAFO RETIRADO_x000D_ POTÊNCIA : 15KVA_x000D_ TENSÃO : 34,5KV_x000D_ Nº ENERGISA (CITD) : 127855_x000D_ Nº DE SÉRIE : 573101_x000D_ MARCA : TRAEL_x000D_ DATA FABRICAÇÃO : 04/2021_x000D_ IMPEDANCIA : 3,0_x000D_ POS. TAP : 03_x000D_ _x000D_ TRAFO INSTALADO_x000D_ POTÊNCIA : 15KVA_x000D_ TENSÃO : 34,5KV_x000D_ Nº ENERGISA (CITD) : 149670_x000D_ Nº DE SÉRIE : C290231_x000D_ MARCA : ITAM_x000D_ DATA FABRICAÇÃO : 09/2025_x000D_ IMPEDANCIA : 3,13_x000D_ POS. TAP : 03_x000D_ _x000D_ MEDIÇÃO 1: 21,20_x000D_ MEDIÇÃO 2: 17,45_x000D_ MEDIÇÃO 3: 12,76_x000D_ _x000D_ COORDENADA_x000D_ X: 893367_x000D_ Y: 9000689 | F19: QUEIMADO | G19: DESCARGA ATMOSFÉRICA | H19: QUEIMADO | I19: DESCARGA ATMOSFÉRICA | J19: MC - SUBSTITUIÇÃO DE TRANSFORMADOR | K19: 2026 | L19: LD01065015 | M19: 5700026195 | N19: 8812 | O19: EMERGENCIAL | P19: SS ATENDIDA | Q19: 46028.697 | R19: 46029.87 | S19: 46031.697 | T19: BLOCO TRANSFORMADOR DE DISTRIBUIÇÃO | U19: CENTENARIO | V19: STANLEY APARECIDO DO CARMO | W19: RURAL | X19: FORMS SUBST DE TRANSFORMADOR | Y19: Trafo: 5700026195 Queimado Potencia: 15 KVATensão: 34,5 KVPara raio: queimado Acesso: Camioneta Equipe: 227op01 (63)99247-2838/99928-1276 | Z19: 15 | AA19: 15 | AB19: 15 KVA | AC19: 46225.761
A20: ETO-RD-AG 00184/2026 | B20: ENC-MPAG02 000022/2026 | C20: 662600115 | E20: 5748172045 QUEIMADO _x000D_ POT. 45KVA_x000D_ 34,5KV_x000D_ PARA-RAIO BT E MT RUIM_x000D_ ACESSO BOM_x000D_ RDR SAMPAIO_x000D_ _x000D_ _x000D_ TRAFO Nº _x000D_ _x000D_ TRAFO RETIRADO_x000D_ _x000D_ POTÊNCIA; 45VKA 34,5KV_x000D_ POS. DO TAP; 2º_x000D_ DATA DE FAB; 02/2015 REFORMA; 05/2024_x000D_ MARCA; TRAEL - TRAEL PA_x000D_ Nº CITD; 113354_x000D_ Nº SÉRIE; 460414_x000D_ IMPEDÂNCIA; 3,72_x000D_ _x000D_ TRAFO INSTALADO _x000D_ _x000D_ POTÊNCIA; 45KVA 34,5KV_x000D_ POS. DO TAP; 2º _x000D_ DATA DE FAB; 01/2023 REFORMA 04/2025_x000D_ MARCA; ITAIPU / TRAEL PA_x000D_ Nº CITD; 134715_x000D_ Nº SÉRIE; 487471_x000D_ IMPEDÂNCIA; 4_x000D_ MEDIÇÃO; 5,43 / 5,44 / 5,99_x000D_ _x000D_ | F20: QUEIMADO | G20: DESCARGA ATMOSFÉRICA | H20: QUEIMADO | I20: DESCARGA ATMOSFÉRICA | J20: MC - SUBSTITUIÇÃO DE TRANSFORMADOR | K20: 2026 | L20: LD02014045 | M20: 5748172045 | N20: 8385 | O20: EMERGENCIAL | P20: SS ATENDIDA | Q20: 46066.724 | R20: 46066.949 | S20: 46069.724 | T20: BLOCO TRANSFORMADOR DE DISTRIBUIÇÃO | U20: SAMPAIO | V20: ARTHUR MAGALHAES DAS DORES | W20: RURAL | X20: AVISO DE ANOMALIA | Y20: 5748172045 QUEIMADO POT. 45KVA34,5KVPARA-RAIO BT E MT RUIMACESSO BOMRDR SAMPAIO | Z20: 45 | AA20: 45 | AC20: 46225.761
A21: DOLP-RD-PA 00246/2026 | B21: DLP-MLPA01 000058/2026 | C21: 112600239 | E21: MEDIDO__x000D_ _x000D_ EMERGENCIAL__x000D_ _x000D_ segue nota de trafo queimado, trafo 5712754122, trafo de 15kva, tensao 34500 / 440 V, acesso livre, para-raio danificado_x000D_ _x000D_ _x000D_ DADOS ATENDIMENTO_x000D_ _x000D_ EQUIPE: PALMA04M_x000D_ LIDER: JOSE RAIMUNDO LOPES DE SOUZA _x000D_ CONTATO: 63 9296-9610_x000D_ DOLP-RD-PA 000246/2026_x000D_ DATA ATENDIMENTO: 12/02/2026_x000D_ _x000D_ Atenção!_x000D_ Não intervenha na rede sem autorização do COI (Centro de Operações Integradas) | F21: QUEIMADO | G21: DESCARGA ATMOSFÉRICA | H21: QUEIMADO | I21: DESCARGA ATMOSFÉRICA | J21: MC - SUBSTITUIÇÃO DE TRANSFORMADOR | K21: 2026 | L21: LD02059122 | M21: 5712754122 | N21: 8812 | O21: EMERGENCIAL | P21: SS ATENDIDA | Q21: 46064.804 | R21: 46065.447 | S21: 46067.804 | T21: BLOCO TRANSFORMADOR DE DISTRIBUIÇÃO | U21: PALMAS | V21: MARCO ANTONIO LOURENCO CAMPOS | W21: RURAL | X21: FORMS SUBST DE TRANSFORMADOR | Y21: segue nota de trafo queimado, trafo 5712754122, trafo de 15kva, tensao 34500 / 440 V, acesso livre, para-raio danificado | Z21: 25 | AA21: 15 | AB21: 15kva | AC21: 46225.761
A22: DG-RD-PO 00159/2026 | B22: DG-MLPO01 000034/2026 | C22: 312600124 | E22: medido__x000D_ emergencial__x000D_ _x000D_ _x000D_ Trafo 5700799026 de 15kva e para-raio queimado, Tensão 19,9kv, Acesso para camionete 4x4, Local Rural de Ponte Alta, Faz. IND FAZENDA RESERVA, 0 - LPT -13290 FAZ. RESERVA_x000D_ | F22: QUEIMADO | G22: DESCARGA ATMOSFÉRICA | H22: QUEIMADO | I22: DESCARGA ATMOSFÉRICA | J22: MC - SUBSTITUIÇÃO DE TRANSFORMADOR | K22: 2026 | L22: LD03046026 | M22: 5700799026 | N22: 8812 | O22: EMERGENCIAL | P22: SS ATENDIDA | Q22: 46057.139 | R22: 46058.504 | S22: 46060.139 | T22: BLOCO TRANSFORMADOR DE DISTRIBUIÇÃO | U22: PONTE ALTA DO TOCANTINS | V22: SAMUEL PINTO GOMES | W22: RURAL | X22: FORMS SUBST DE TRANSFORMADOR | Y22: Trafo 5700799026 de 15kva e para-raio queimado, Tensão 19,9kv, Acesso para camionete 4x4, Local Rural de Ponte Alta, Faz. IND FAZENDA RESERVA, 0 - LPT -13290 FAZ. RESERVA | Z22: 15 | AA22: 5 | AB22: 15kva | AC22: 46225.761
A23: ETO-RD-AG 00315/2026 | B23: ETO-RD-AG 000273/2026 | C23: 662600206 | E23: TROCAR TRECHO DE REDE BT NO CIRCUITO DO TRAFO 5700383123._x000D_ _x000D_ ---->NOTA AC_x000D_ SUBST 02 VÃO DE REDE CABO 04AWG CA DE 60MT X02 DE CABO 04AWG CA POR CABO 04AWG CAA ENTRE OS PORTES ID-68454819 AO POSTE ID-68428603._x000D_ _x000D_ SUBST 01 VÃO DE REDE CABO 35mm MONOFASICO MULTIPLEXADO DE 45MT POR CABO 35mm BIFASICO MULTIPLEX ENTRE OS PORTES ID-68455048 AO POSTE ID-68428603._x000D_ _x000D_ _x000D_ INTERCALADO 01 POSTE 10/600 DT SI4 ENTRE OS PORTES ID-68428603 AO POSTE ID*-68455048. | F23: GARANTIA DE TRAFO | G23: VEGETAÇÃO | H23: GARANTIA DE TRAFO | I23: VEGETAÇÃO | J23: MC - CONEXÃO MT | K23: 2026 | L23: LD01084002 | M23: 5700373123 | N23: 8389 | O23: EMERGENCIAL | P23: SS ATENDIDA | Q23: 46101.378 | R23: 46101.583 | S23: 46104.378 | T23: TRANSFORMADOR DE DISTRIBUIÇÃO ENERGISA 19919Kv | U23: AGUIARNOPOLIS | V23: ADRIANO DE SOUSA GOMES | W23: RURAL | X23: SOLICITAÇÃO DE SERVIÇO | Y23: TROCAR TRECHO DE REDE BT NO CIRCUITO DO TRAFO 5700383123.50 METROS DE REDE COMPACTA (DP/10)80 METROS DE REDE CABO NU. (DU/35) | AC23: 46225.761
A24: DG-RD-PO 00189/2026 | B24: DG-MLPO01 000041/2026 | C24: 312600152 | E24: medido__x000D_ emergencial__x000D_ _x000D_ _x000D_ 5701005096 15kva e para queimado 19,9 acessol livre equipé 096op01 992607520_x000D_ | F24: QUEIMADO | G24: DESCARGA ATMOSFÉRICA | H24: QUEIMADO | I24: DESCARGA ATMOSFÉRICA | J24: MC - SUBSTITUIÇÃO DE TRANSFORMADOR | K24: 2026 | L24: LD03046026 | M24: 5701005096 | N24: 8812 | O24: EMERGENCIAL | P24: SS ATENDIDA | Q24: 46067.499 | R24: 46067.799 | S24: 46070.499 | T24: TRANSFORMADOR DE DISTRIBUIÇÃO ENERGISA 19.919Kv | U24: PINDORAMA DO TOCANTINS | V24: CLEONE PEREIRA DE SOUZA LIMA | W24: RURAL | X24: FORMS SUBST DE TRANSFORMADOR | Y24: 5701005096 15kva e para queimado 19,9 acessol livre equipé 096op01 992607520 | Z24: 15 | AA24: 5 | AB24: 15kva | AC24: 46225.761
A25: DG-RD-PO 00198/2026 | B25: DG-MLPO01 000048/2026 | C25: 312600158 | E25: medido__x000D_ emergencial__x000D_ _x000D_ _x000D_ INT: 20264128798303_x000D_ Segue SS de TR 5700905152 15KVA/19.9KV e para-raios queimados._x000D_ Acesso somente para caminhonete_x000D_ UC 10433800_x000D_ FAZENDA BOA VISTA_x000D_ 63992761180_x000D_ ADAILDA RIBEIRO RODRIGUES_x000D_ 152OP01 63 98413-9467_x000D_ | F25: QUEIMADO | G25: DESCARGA ATMOSFÉRICA | H25: QUEIMADO | I25: DESCARGA ATMOSFÉRICA | J25: MC - SUBSTITUIÇÃO DE TRANSFORMADOR | K25: 2026 | L25: LD02072001 | M25: 5700905152 | N25: 8812 | O25: EMERGENCIAL | P25: SS ATENDIDA | Q25: 46069.668 | R25: 46071.743 | S25: 46072.668 | T25: TRANSFORMADOR DE DISTRIBUIÇÃO ENERGISA 19.919Kv | U25: SANTA ROSA DO TOCANTINS | V25: JOSE MARIA ALVES MONTEL | W25: RURAL | X25: FORMS SUBST DE TRANSFORMADOR | Y25: INT: 20264128798303Segue SS de TR 5700905152 15KVA/19.9KV e para-raios queimados.Acesso somente para caminhoneteUC 10433800FAZENDA BOA VISTA63992761180ADAILDA RIBEIRO RODRIGUES152OP01 63 98413-9467 | Z25: 15 | AA25: 5 | AB25: 15 | AC25: 46225.761
A26: ETO-RD-DP 00128/2026 | B26: ETO-MLDP01 000057/2026 | C26: 512600085 | E26: Foi constatado Trafo 5726149027 15kva 19,9kv e para-raios Queimados | F26: QUEIMADO | G26: DESCARGA ATMOSFÉRICA | H26: QUEIMADO | I26: DESCARGA ATMOSFÉRICA | J26: MC - SUBSTITUIÇÃO DE TRANSFORMADOR | K26: 2026 | L26: LD01414027 | M26: 5726149027 | N26: 8812 | O26: EMERGENCIAL | P26: SS ATENDIDA | Q26: 46072.88 | R26: 46074.565 | S26: 46075.88 | T26: BLOCO TRANSFORMADOR DE DISTRIBUIÇÃO | U26: PONTE ALTA DO BOM JESUS | V26: GILMAR VIEIRA DE SOUSA | W26: RURAL | X26: FORMS SUBST DE TRANSFORMADOR | Y26: Foi constatado Trafo 5726149027 15kva 19,9kv e para-raios Queimados | Z26: 15 | AA26: 15 | AB26: 15kva | AC26: 46225.761
A27: ETO-RD-GU 00261/2026 | B27: DBM-MLDB04 000066/2026 | C27: 412600249 | E27: SUBSTITUIÇÃO DE TRANSFORMADOR NA RDR DE GURUPI_x000D_ _x000D_ INT: 20264133735727_x000D_ _x000D_ SS: ETO-RD-GU 261/2026_x000D_ _x000D_ ESPECIFICAÇÕES DO TRANSFORMADOR_x000D_ _x000D_ TRANSFORMADOR INSTALADO: 15KVA_x000D_ _x000D_ TRANSFORMADOR RETIRADO: 15KVA_x000D_ _x000D_ MEDIÇÕES_x000D_ _x000D_ LOGO APÓS A TROCA _x000D_ _x000D_ VAN: 221.3_x000D_ _x000D_ OBS:SUBSTITUIÇÃO DE TRANSFORMADOR AUTORIZADA PELO DIONE._x000D_ _x000D_ | F27: QUEIMADO | G27: DESCARGA ATMOSFÉRICA | H27: QUEIMADO | I27: DESCARGA ATMOSFÉRICA | J27: MC - SUBSTITUIÇÃO DE TRANSFORMADOR | K27: 2026 | L27: LD04040003 | M27: 5362153003 | N27: 8812 | O27: EMERGENCIAL | P27: SS ATENDIDA | Q27: 46076.711 | R27: 46078.446 | S27: 46079.711 | T27: BLOCO TRANSFORMADOR DE DISTRIBUIÇÃO | U27: GURUPI | V27: HELDER SILVA CARVALHO | W27: RURAL | X27: FORMS SUBST DE TRANSFORMADOR | Y27: Transformador queimado 5362153003, potencia 15kva, tensão 19.9, acesso livre a camionete , para raio queimado, causa descarga atmosférica, feito teste a vazio.telefone 63992666663 equipe 003op13 | Z27: 15 | AA27: 15 | AB27: 15 | AC27: 46225.761
A28: ETO-RD-AR 00198/2026 | B28: ENC-MLAR05 000069/2026 | C28: 612600130 | E28: ETO-RD-AR 198/2026_x000D_ TR: 5710365060_x000D_ N° CHAVE: 0310365060_x000D_ _x000D_ TRAFO RETIRADO_x000D_ POTÊNCIA : 15KVA_x000D_ TENSÃO : 13,8KV_x000D_ Nº ENERGISA (CITD) : 116756_x000D_ Nº DE SÉRIE : 473495_x000D_ MARCA : TRAEL_x000D_ DATA FABRICAÇÃO : 06/2018_x000D_ IMPEDANCIA : 2,62_x000D_ POS. TAP : 03_x000D_ _x000D_ TRAFO INSTALADO_x000D_ POTÊNCIA : 15KVA_x000D_ TENSÃO : 13,8KV_x000D_ Nº ENERGISA (CITD) : 148486_x000D_ Nº DE SÉRIE : C289650_x000D_ MARCA : ITAM_x000D_ DATA FABRICAÇÃO : 09/2025_x000D_ IMPEDANCIA : 2,54_x000D_ POS. TAP : 3_x000D_ | F28: QUEIMADO | G28: DESCARGA ATMOSFÉRICA | H28: QUEIMADO | I28: DESCARGA ATMOSFÉRICA | J28: MC - SUBSTITUIÇÃO DE TRANSFORMADOR | K28: 2026 | L28: AL01054060 | M28: 5710365060 | N28: 8812 | O28: EMERGENCIAL | P28: SS ATENDIDA | Q28: 46053.747 | R28: 46054.729 | S28: 46056.747 | T28: BLOCO TRANSFORMADOR DE DISTRIBUIÇÃO | U28: NOVA OLINDA | V28: MAIKOM DOUGLAS DA SILVA | W28: RURAL | X28: FORMS SUBST DE TRANSFORMADOR | Y28: Boa tarde,Favor enviar manutenção para subsituitr trafo queimado 5710365060 | Z28: 15 | AA28: 15 | AB28: 15 | AC28: 46225.761
A29: ETO-RD-GR 00387/2026 | B29: ENC-MLAR03 000028/2026 | C29: 712600276 | E29: TROCA DE TRAFO AVARIADO 5700018155 ETO-RD-GR 387/2026 ZONA RURAL - PALMEIRANTE 0155_x000D_ _x000D_ TRAFO RETIRADO_x000D_ POTÊNCIA : 25KVA_x000D_ TENSÃO : 19.9KV _x000D_ Nº ENERGISA (CITD) : ILEGIVEL_x000D_ Nº DE SÉRIE : 352737_x000D_ MARCA : TRAEL_x000D_ DATA FABRICAÇÃO : 10/2015_x000D_ IMPEDANCIA : 2.84_x000D_ POS. TAP : 03_x000D_ _x000D_ TRAFO INSTALADO_x000D_ POTÊNCIA : 15KVA_x000D_ TENSÃO : 19.9KV _x000D_ Nº ENERGISA (CITD) : 150227_x000D_ Nº DE SÉRIE : 827950_x000D_ MARCA : TRAEL_x000D_ DATA FABRICAÇÃO : 02/2026_x000D_ IMPEDANCIA : 3.0_x000D_ POS. TAP : 03_x000D_ _x000D_ MEDIÇÃO 1: 07.95_x000D_ MEDIÇÃO 2: 06.50_x000D_ MEDIÇÃO 3: 05.83_x000D_ _x000D_ COORDENADA_x000D_ X: 828148_x000D_ Y: 9148054_x000D_ _x000D_ _x000D_ _x000D_ SERVIÇO EM CONJUNTO COM A OS ENC-MLAR03 29/2026. | F29: AVARIADO | G29: VAZAMENTO DE ÓLEO | H29: AVARIADO | I29: VAZAMENTO DE ÓLEO | J29: MC - SUBSTITUIÇÃO DE TRANSFORMADOR | K29: 2026 | L29: LD02105019 | M29: 5700018155 | N29: 8812 | O29: EMERGENCIAL | P29: SS ATENDIDA | Q29: 46108.409 | R29: 46108.708 | S29: 46111.409 | T29: BLOCO TRANSFORMADOR DE DISTRIBUIÇÃO | U29: PALMEIRANTE | V29: VALERIA DE JESUS BORGES CARVAL | W29: RURAL | X29: FORMS SUBST DE TRANSFORMADOR | Y29: trafo 5700018155 com vazamento de óleo - 25KVA - 19,9KV - para raio queimado substituir poste 10/200 estrutura U1/S1 - danificado na base. RDU do Povoado Cicilândia RDR Palmeirante | Z29: 15 | AA29: 25 | AB29: 25KVA | AC29: 46225.761
A30: ETO-RD-GU 00239/2026 | B30: DBM-MPDB08 000051/2026 | C30: 412600226 | E30: SUBSTITUIÇÃO DE TRANSFORMADOR NA RDR DE ARAGUAÇU_x000D_ _x000D_ INT: 20264133090042_x000D_ _x000D_ SS: ETO-RD-GU 239/2026_x000D_ _x000D_ ESPECIFICAÇÕES DO TRANSFORMADOR_x000D_ _x000D_ TRANSFORMADOR INSTALADO: 75 KVA_x000D_ _x000D_ TRANSFORMADOR RETIRADO: 75 KVA_x000D_ _x000D_ MEDIÇÕES_x000D_ _x000D_ LOGO APÓS A TROCA _x000D_ _x000D_ VAN: 223_x000D_ _x000D_ VBN: 223_x000D_ _x000D_ OBS:SUBSTITUIÇÃO DE TRANSFORMADOR AUTORIZADA PELO DIONE._x000D_ | F30: QUEIMADO | G30: DESCARGA ATMOSFÉRICA | H30: QUEIMADO | I30: DESCARGA ATMOSFÉRICA | J30: MC - SUBSTITUIÇÃO DE TRANSFORMADOR | K30: 2026 | L30: LD01003036 | M30: 5764992032 | N30: 8812 | O30: EMERGENCIAL | P30: SS ATENDIDA | Q30: 46073.802 | R30: 46077.255 | S30: 46076.802 | T30: BLOCO TRANSFORMADOR DE DISTRIBUIÇÃO | U30: ARAGUACU | V30: JONATAN ALVES DE SOUZA | W30: RURAL | X30: FORMS SUBST DE TRANSFORMADOR | Y30: SEGUE SOLICITAÇÃO DE SERVIÇO PARA TROCA DE TRAFO QUEIMADO NA RDR DE ARAGUAÇU | Z30: 75 | AA30: 75 | AB30: 75KVA | AC30: 46225.761
A31: ETO-RD-AR 00456/2026 | B31: ETO-RD-AR 000572/2026 | C31: 612600315 | E31: TRAFO 5762725060 QUEIMADO TRIFASICO DE 75 KVA NA REDE 13.8 KV ACESSO BOM FEITO TESTE AVAZIO PARA RAIO BOM REDUE DE NOVA OLINDA | F31: QUEIMADO | G31: DESCARGA ATMOSFÉRICA | H31: QUEIMADO | I31: DESCARGA ATMOSFÉRICA | J31: MC - FERRAGENS | K31: 2026 | L31: AL02054060 | M31: 5762725060 | N31: 8812 | O31: EMERGENCIAL | P31: SS ATENDIDA | Q31: 46092.545 | R31: 46093.641 | S31: 46095.545 | T31: BLOCO TRANSFORMADOR DE DISTRIBUIÇÃO | U31: NOVA OLINDA | V31: PAULO SERGIO CAETANO FREIRE | W31: URBANO | X31: FORMS SUBST DE TRANSFORMADOR | Y31: TRAFO 5762725060 QUEIMADO TRIFASICO DE 75 KVA NA REDE 13.8 KV ACESSO BOM FEITO TESTE AVAZIO PARA RAIO BOM REDUE DE NOVA OLINDA | AB31: 75 KVA | AC31: 46225.761
A32: ETO-RD-GU 00427/2026 | B32: DBM-MLDB05 000083/2026 | C32: 412600351 | E32: SUBSTITUIÇÃO DE TRANSFORMADOR NA RDR DE SANDOLÂNDIA_x000D_ _x000D_ INT: 20264254458485_x000D_ _x000D_ SS: ETO-RD-GU 427/2026_x000D_ _x000D_ ESPECIFICAÇÕES DO TRANSFORMADOR_x000D_ _x000D_ TRANSFORMADOR INSTALADO: 15KVA_x000D_ _x000D_ TRANSFORMADOR RETIRADO: 15KVA_x000D_ _x000D_ MEDIÇÕES_x000D_ _x000D_ LOGO APÓS A TROCA _x000D_ _x000D_ VAN: 224.7_x000D_ _x000D_ OBS:SUBSTITUIÇÃO DE TRANSFORMADOR AUTORIZADA PELO DIONE._x000D_ _x000D_ _x000D_ | F32: QUEIMADO | G32: BUCHA DANIFICADA | H32: QUEIMADO | I32: BUCHA DANIFICADA | J32: MC - SUBSTITUIÇÃO DE TRANSFORMADOR | K32: 2026 | L32: LD01003036 | M32: 5700574107 | N32: 8812 | O32: EMERGENCIAL | P32: SS ATENDIDA | Q32: 46117.676 | R32: 46118.766 | S32: 46120.676 | T32: BLOCO TRANSFORMADOR DE DISTRIBUIÇÃO | U32: SANDOLANDIA | V32: JONATAN ALVES DE SOUZA | W32: RURAL | X32: FORMS SUBST DE TRANSFORMADOR | Y32: SEGUE SOLICITAÇÃO DE SERVIÇO PARA TROCA DE TRAFO QUEIMADO NA RDR DE SANDOLANDIA E COM MUITO VAZAMENTO DE OLEO BUCHA SECUNDARIA ESTOURADA | Z32: 15 | AA32: 15 | AB32: 15KVA | AC32: 46225.761
A33: ETO-RD-AR 00261/2026 | B33: ENC-MLAR05 000107/2026 | C33: 612600165 | E33: SS ETO-RD-AR 261/2026_x000D_ TRAFO 5700041030_x000D_ _x000D_ _x000D_ _x000D_ TRAFO RETIRADO_x000D_ POTÊNCIA : 30KVA_x000D_ TENSÃO : 13.8KV_x000D_ Nº ENERGISA (CITD) : 1337_x000D_ Nº DE SÉRIE : 3398_x000D_ MARCA : PCG_x000D_ DATA FABRICAÇÃO : 1976_x000D_ IMPEDANCIA : 3.45_x000D_ POS. TAP : 02_x000D_ _x000D_ TRAFO INSTALADO'_x000D_ POTÊNCIA : 30KVA_x000D_ TENSÃO : 13.8KV_x000D_ Nº ENERGISA (CITD) : 147756_x000D_ Nº DE SÉRIE : 586793_x000D_ MARCA : ITAIPU_x000D_ DATA FABRICAÇÃO : 07/2025_x000D_ IMPEDANCIA : 3.56_x000D_ POS. TAP : 02_x000D_ | F33: AVARIADO | G33: VAZAMENTO DE ÓLEO | H33: AVARIADO | I33: VAZAMENTO DE ÓLEO | J33: MC - SUBSTITUIÇÃO DE TRANSFORMADOR | K33: 2026 | L33: AL01087030 | M33: 5700041030 | N33: 25962 | O33: EMERGENCIAL | P33: SS ATENDIDA | Q33: 46060.44 | R33: 46061.681 | S33: 46063.44 | T33: BLOCO TRANSFORMADOR DE DISTRIBUIÇÃO | U33: XAMBIOA | V33: EZEQUIEL CAVALCANTE DOS SANTOS | W33: URBANO | X33: FORMS SUBST DE TRANSFORMADOR | Y33: Substitui trafo 5700041030 potencia 30kva tensão 13,8kv vazamento de óleo acesso livre. Equipe solicitou para reposicionar na chave do trafo para facilitar a abertura da mesma. | Z33: 30 | AA33: 30 | AB33: 30 | AC33: 46225.761
A34: ETO-RD-AR 00267/2026 | B34: ENC-MLAR01 000076/2026 | C34: 612600168 | E34: SS ETO-RD-AR 267/2026_x000D_ TRAFO: 5700416016_x000D_ _x000D_ _x000D_ _x000D_ TRAFO RETIRADO_x000D_ POTÊNCIA : 5KVA_x000D_ TENSÃO : 34.5KV_x000D_ Nº ENERGISA (CITD) : ILEGIVEL_x000D_ Nº DE SÉRIE : 480845_x000D_ MARCA : ITB_x000D_ DATA FABRICAÇÃO : AGO/2007_x000D_ IMPEDANCIA : 2.78_x000D_ POS. TAP : 02_x000D_ _x000D_ TRAFO INSTALADO'_x000D_ POTÊNCIA : 15KVA_x000D_ TENSÃO : 34.5KV_x000D_ Nº ENERGISA (CITD) : 149188_x000D_ Nº DE SÉRIE : 820174_x000D_ MARCA : TRAEL_x000D_ DATA FABRICAÇÃO : 11/2025_x000D_ IMPEDANCIA : 3.0_x000D_ POS. TAP : 03_x000D_ | F34: QUEIMADO | G34: NÃO IDENTIFICADO | H34: QUEIMADO | I34: DESCARGA ATMOSFÉRICA | J34: MC - SUBSTITUIÇÃO DE TRANSFORMADOR | K34: 2026 | L34: LD02010004 | M34: 5700416016 | N34: 8812 | O34: EMERGENCIAL | P34: SS ATENDIDA | Q34: 46061.405 | R34: 46062.712 | S34: 46064.405 | T34: BLOCO TRANSFORMADOR DE DISTRIBUIÇÃO | U34: WANDERLANDIA | V34: LEANDRO BISPO DE BARROS | W34: RURAL | X34: FORMS SUBST DE TRANSFORMADOR | Y34: trafo 5700416016 queimado pararaios danificados acesso livre | Z34: 15 | AA34: 5 | AB34: 5kva | AC34: 46225.761
A35: ETO-RD-AG 00361/2026 | B35: ETO-RD-AG 000319/2026 | C35: 662600216 | E35: PLANO DE MEDIDA - Realizar substituição do trafo 5700133123 de 10 kVA para 15 kVA | F35: SOBRECARGA PREVENTIVA | G35: SOBRECARGA | H35: SOBRECARGA PREVENTIVA | I35: SOBRECARGA | J35: MC - SUBSTITUIÇÃO DE TRANSFORMADOR | K35: 2026 | L35: LD01084002 | M35: 5700133123 | N35: 25983 | O35: EMERGENCIAL | P35: SS ATENDIDA | Q35: 46113.664 | R35: 46114.032 | S35: 46116.664 | T35: BLOCO TRANSFORMADOR DE DISTRIBUIÇÃO | U35: AGUIARNOPOLIS | V35: ADRIANO DE SOUSA GOMES | W35: RURAL | X35: AVISO DE ANOMALIA | Y35: TR 5700133123 QueimadoPotencia: 10 Kva tensão 34,5 kva, acesso para acaminhão | AB35: 10 kva | AC35: 46225.761
A36: ETO-RD-GU 00626/2026 | B36: DBM-MLDB05 000100/2026 | C36: 412600501 | E36: SEGUE SOLICITAÇÃO DE SERVIÇO PARA TROCA DE TRAFO QUEIMADO A RDR DE PARANÃ_x000D_ _x000D_ _x000D_ SUBSTITUIÇÃO DE TRANSFORMADOR NA RDR DE PARANÃ_x000D_ _x000D_ INT: 20264514579985_x000D_ _x000D_ SS: ETO-RD-GU 626/2026_x000D_ _x000D_ ESPECIFICAÇÕES DO TRANSFORMADOR_x000D_ _x000D_ TRANSFORMADOR INSTALADO: 15 KVA_x000D_ _x000D_ TRANSFORMADOR RETIRADO: 15 KVA_x000D_ _x000D_ MEDIÇÕES_x000D_ _x000D_ LOGO APÓS A TROCA _x000D_ _x000D_ VAN: 209_x000D_ _x000D_ _x000D_ OBS:SUBSTITUIÇÃO DE TRANSFORMADOR AUTORIZADA PELO DIONE._x000D_ | F36: QUEIMADO | G36: NÃO IDENTIFICADO | H36: QUEIMADO | I36: NÃO IDENTIFICADO | J36: MC - SUBSTITUIÇÃO DE TRANSFORMADOR | K36: 2026 | L36: LD01010021 | M36: 5743917021 | N36: 8812 | O36: EMERGENCIAL | P36: SS ATENDIDA | Q36: 46187.669 | R36: 46188.5 | S36: 46190.669 | T36: BLOCO TRANSFORMADOR DE DISTRIBUIÇÃO | U36: PARANA | V36: JONATAN ALVES DE SOUZA | W36: RURAL | X36: FORMS SUBST DE TRANSFORMADOR | Y36: SEGUE SOLICITAÇÃO DE SERVIÇO PARA TROCA DE TRAFO QUEIMADO A RDR DE PARANÃ | Z36: 15 | AA36: 15 | AB36: 15KVA | AC36: 46225.761
A37: DOLP-RD-PA 00303/2026 | B37: DLP-MPPA01 000076/2026 | C37: 112600434 | E37: MEDIDO__x000D_ trafo 5722285006 vazaMENTO DE Óleo _x000D_ acesso livre _x000D_ potencia 30 kva _x000D_ tensão 34,5 _x000D_ para-raio queimado _x000D_ _x000D_ obs: leva porta fusivel para fecha o trafo_x000D_ _x000D_ _x000D_ _x000D_ DADOS ATENDIMENTO_x000D_ EQUIPE DOLP-MPPA01_x000D_ ENCARREGADO - IBANEZ RODRIGUES_x000D_ _x000D_ SS DOLP-RD-PA 303/2026_x000D_ _x000D_ _x000D_ DATA ATENDIMENTO_x000D_ 03/03/2026_x000D_ _x000D_ _x000D_ _x000D_ CUMPRIR COM TODOS OS PROCEDIMENTOS DE SEGURANÇA_x000D_ _x000D_ _x000D_ _x000D_ *********** Parecer do COCM - ordem de serviço baixada sistemicamente, empreiteira estará fazendo as baixa de material e lançamento de mão de obra. | F37: QUEIMADO | G37: VAZAMENTO DE ÓLEO | H37: QUEIMADO | I37: VAZAMENTO DE ÓLEO | J37: MC - SUBSTITUIÇÃO DE TRANSFORMADOR | K37: 2026 | L37: LD03059122 | M37: 5722285006 | N37: 25962 | O37: EMERGENCIAL | P37: SS ATENDIDA | Q37: 46081.337 | R37: 46104.375 | S37: 46084.337 | T37: BLOCO TRANSFORMADOR DE DISTRIBUIÇÃO | U37: TOCANTINIA | V37: JORGE BOAZ FERREIRA SOUSA DA S | W37: RURAL | X37: FORMS SUBST DE TRANSFORMADOR | Y37: trafo 5722285006 vazaMENTO DE Óleo acesso livre potencia 30 kva tensão 34,5 para-raio queimado obs: leva porta fusivel para fecha o trafo | Z37: 30 | AA37: 30 | AB37: 30 KVA | AC37: 46225.761
A38: DOLP-RD-PA 00685/2026 | B38: DLP-MLPA03 000101/2026 | C38: 112600629 | E38: MEDIDO__x000D_ _x000D_ EMERGENCIAL__x000D_ _x000D_ ATIVO: 190.02545117_x000D_ LOCALIZAÇÃO: 190-13651952_x000D_ _x000D_ segue ss de 01 trafo 15 kva e 01 para raio da rede de 34.500kv queimado para ser subistituido pela equipe de manutencão acesso só caminhonete cliente penalizado 1 equipe que atendeu 151op01 cel, 63992044413/992447381 favor agilizar o atendimento chave de referencia. 5700318196_x000D_ _x000D_ DADOS ATENDIMENTO_x000D_ _x000D_ N° DOCUMENTO SS: DOLP-RD-PA 000685/2026_x000D_ N° DOCUMENTO OS: DLP-MLPA03 000000/2026_x000D_ _x000D_ TIPO DA INTERVENÇÃO: MANUTENÇÃO_x000D_ TIPO DO SERVIÇO: SUBSTITUIÇÃO DE TRANSFORMADOR E MELHORIA DE MALHA DE ATERRAMENTO_x000D_ DATA PROGRAMADA DA ATIVIDADE: 25/05/2026 A 30/05/2026_x000D_ HORARIO PREVISTO DA ATIVIDADE: 08:00 ÀS 18:00_x000D_ CIDADE: LAGOA DO TOCANTINS - ALIMENTADOR: LD02059122 - TRANSFORMADOR: 5700318196_x000D_ _x000D_ _x000D_ _x000D_ EQUIPE: DOLP-MLPA05_x000D_ CONTATO DA EQUIPE: 63 9296-7129_x000D_ COMPOSIÇÃO DA EQUIPE:_x000D_ 1 - EDUARDO DA SILVA SANTOS_x000D_ 2 - JOÃO CLAUDIO SACRAMENTO_x000D_ _x000D_ _x000D_ _x000D_ SUPERVISOR: PAULO VÍTOR LEMES GOMES CONTATO: 63 9 9296-6939_x000D_ FISCAL RESPONSAVEL: JOELSON SILVA DE SOUZA_x000D_ _x000D_ Atenção!_x000D_ _x000D_ A segurança é o nosso "Peso 10" e nenhuma urgência operacional justifica a exposição ao risco!_x000D_ _x000D_ * Utilize os equipamentos de proteção de acordo com a classe de tensão da rede._x000D_ * Reforçamos a obrigatoriedade sempre que for realizar manobra de ré, ou manobras que envolvam potenciais riscos existentes o apoio em terra de um dos parceiros da equipe._x000D_ * A velocidade deve ser compatível com a via e as condições climáticas no momento da direção._x000D_ * Toda intervenção deve seguir protocolos de segurança, não intervenha sem autorização do COI (Centro de Operações Integrado)._x000D_ _x000D_ _x000D_ Atenção Redobrada no Final do Turno!_x000D_ _x000D_ * Descanso é Regra: Os horários de refeição e descanso devem ser respeitados integralmente. Eles são o que garante a sua energia para a continuidade do trabalho._x000D_ * Saúde e Bem-estar: Mantenha a hidratação e use o protetor solar. O desgaste físico interfere diretamente na sua tomada de decisão._x000D_ * Manobras de Risco: Nunca realize manobras críticas ou de ré sem o apoio em solo de um parceiro. O olhar externo é sua maior proteção._x000D_ * Condições Climáticas: Em caso de chuvas fortes que diminuam a visibilidade, reduza a velocidade imediatamente. Se necessário, pare o veículo em local seguro até que as condições melhorem._x000D_ * Comunicação Aberta: Sinalize à supervisão qualquer condição anormal, inclusive questões de relacionamento com o parceiro. Unidade na equipe é segurança na rede._x000D_ * Que todos tenham um excelente e seguro retorno. Missão cumprida é missão com Zero Acidentes!_x000D_ _x000D_ Nós somos o que fazemos e fazemos o que acreditamos! | F38: QUEIMADO | G38: NÃO IDENTIFICADO | H38: QUEIMADO | I38: NÃO IDENTIFICADO | J38: MC - SUBSTITUIÇÃO DE TRANSFORMADOR | K38: 2026 | L38: LD02059122 | M38: 5700318196 | N38: 8812 | O38: EMERGENCIAL | P38: SS ATENDIDA | Q38: 46190.644 | R38: 46191.75 | S38: 46193.644 | T38: BLOCO TRANSFORMADOR DE DISTRIBUIÇÃO | U38: LAGOA DO TOCANTINS | V38: JOAO PAULO VASCONCELOS MARINHO | W38: RURAL | X38: FORMS SUBST DE TRANSFORMADOR | Y38: segue ss de 01 trafo 15 kva e 01 para raio da rede de 34.500kv queimado para ser subistituido pela equipe de manutencão acesso só caminhonete cliente penalizado 1 equipe que atendeu 151op01 cel, 63992044413/992447381 favor agilizar o atendimento chave de referencia. 5700318196 | Z38: 15 | AA38: 15 | AB38: 15 kvar rede de 34,500kv | AC38: 46225.761
A39: ETO-RD-GR 00720/2026 | B39: ENC-MPGR01 000147/2026 | C39: 712600460 | E39: INSTALAÇÃO DE POSTO DE TRANSFORMAÇÃO EM NOVA DIVISÃO DE CIRCUITO ETO-RD-GR 720/2026 ZONA URBANA - TUPIRATINS 0066_x000D_ _x000D_ TRAFO INSTALADO_x000D_ POTÊNCIA : 25KVA_x000D_ TENSÃO : 19.9KV _x000D_ Nº ENERGISA (CITD) : 151765_x000D_ Nº DE SÉRIE : Z 308332_x000D_ MARCA : ITAM_x000D_ DATA FABRICAÇÃO : 04/2026_x000D_ IMPEDANCIA : 2.78_x000D_ POS. TAP : 03_x000D_ _x000D_ MEDIÇÃO 1: 13.74_x000D_ MEDIÇÃO 2: 09.97_x000D_ MEDIÇÃO 3: 05.93_x000D_ _x000D_ COORDENADA_x000D_ X: 816827_x000D_ Y: 9072112_x000D_ | H39: SOBRECARGA PREVENTIVA | I39: SOBRECARGA | J39: MC - SUBSTITUIÇÃO DE TRANSFORMADOR | K39: 2026 | L39: LD03038009 | M39: 5720015066 | N39: 8389 | O39: EMERGENCIAL | P39: SS ATENDIDA | Q39: 46217.472 | R39: 46217.729 | S39: 46220.472 | T39: BLOCO TRANSFORMADOR DE DISTRIBUIÇÃO | U39: TUPIRATINS | V39: LEONARDO SANTOS DA SILVA | W39: RURAL | X39: AVISO DE ANOMALIA | Y39: Divisão de circuito emergencial do trafo 5720015066 | Z39: 25 | AA39: 5 | AC39: 46225.761
A40: ETO-RD-AG 00485/2026 | B40: ENC-MLAG01 000119/2026 | C40: 662600296 | E40: OS PARA SUBSTITUICAO DE TRAFO QUEIMADO_x000D_ _x000D_ _x000D_ TRAFO Nº 5700597119_x000D_ _x000D_ TRANSFORMAR RETIRADO_x000D_ _x000D_ POTÊNCIA; 05KVA 34,5KV_x000D_ DATA DE FAB; AGOSTO/2010_x000D_ MARCA; ITB_x000D_ Nº CITD; 40034_x000D_ Nº SÉRIE; 691095_x000D_ POS. DO TAP; 3º_x000D_ IMPEDÂNCIA; 3,15_x000D_ _x000D_ TRAFO INSTALADO _x000D_ _x000D_ _x000D_ POTÊNCIA; 15KVA 34,5KV_x000D_ DATA DE FAB; FEV/2026_x000D_ MARCA; TRAEL_x000D_ Nº CITD; 150329_x000D_ Nº SÉRIE; 828052_x000D_ POS. DO TAP; 3º_x000D_ IMPEDÂNCIA; 3,0_x000D_ MEDIÇÃO; 13,41 / 13,21 / 13,17 | F40: QUEIMADO | G40: DESCARGA ATMOSFÉRICA | H40: QUEIMADO | I40: DESCARGA ATMOSFÉRICA | J40: MC - SUBSTITUIÇÃO DE TRANSFORMADOR | K40: 2026 | L40: LD03005098 | M40: 5700597119 | N40: 8812 | O40: EMERGENCIAL | P40: SS ATENDIDA | Q40: 46149.569 | R40: 46151.404 | S40: 46152.569 | T40: BLOCO TRANSFORMADOR DE DISTRIBUIÇÃO | U40: SAO BENTO DO TOCANTINS | V40: GUILHERME BORGES DE OLIVEIRA | W40: RURAL | X40: FORMS SUBST DE TRANSFORMADOR | Y40: TRAFO 5700597119 15KVA 34.5KV E PARA RAIO QUEIMADOACESSO CAMINHONETELEVAR CARRINHO DE MÃO PARA CARREGAR TRAFO ATE O POSTE. | Z40: 15 | AA40: 5 | AB40: 15KVA | AC40: 46225.761
A41: ENC-RD-PS 00491/2026 | B41: ENC-LMPS03 000079/2026 | C41: 212600455 | E41: SS ENC-RD-PS 491/2026_x000D_ trafo 5700428086 _x000D_ _x000D_ _x000D_ TRAFO RETIRADO_x000D_ POTÊNCIA : 5KVA_x000D_ TENSÃO : 34.5KV_x000D_ Nº ENERGISA (CITD) : ILEGIVEL_x000D_ Nº DE SÉRIE : 128045_x000D_ MARCA : VIJAI_x000D_ DATA FABRICAÇÃO : 10/2008_x000D_ IMPEDANCIA : 3.08_x000D_ POS. TAP : 03_x000D_ _x000D_ TRAFO INSTALADO'_x000D_ POTÊNCIA : 25KVA_x000D_ TENSÃO : 34.5KV_x000D_ Nº ENERGISA (CITD) : 150443_x000D_ Nº DE SÉRIE : 828166_x000D_ MARCA : TRAEL_x000D_ DATA FABRICAÇÃO : 02/2026_x000D_ IMPEDANCIA : 3.0_x000D_ POS. TAP : 03_x000D_ _x000D_ | F41: QUEIMADO | G41: DESCARGA ATMOSFÉRICA | H41: QUEIMADO | I41: DESCARGA ATMOSFÉRICA | J41: MC - SUBSTITUIÇÃO DE TRANSFORMADOR | K41: 2026 | L41: LD03414149 | M41: 5700428086 | N41: 8812 | O41: EMERGENCIAL | P41: SS ATENDIDA | Q41: 46143.475 | R41: 46143.838 | S41: 46146.475 | T41: BLOCO TRANSFORMADOR DE DISTRIBUIÇÃO | U41: MARIANOPOLIS DO TOCANTINS | V41: THIAGO BORGES DE OLIVEIRA | W41: RURAL | X41: FORMS SUBST DE TRANSFORMADOR | Y41: Segue ss para tratativa com equipe de manutençao o quanto antessubstituir trafo 5700428086 queimado na rdr de marianopolis | Z41: 25 | AA41: 5 | AB41: 15 | AC41: 46225.761
A42: ETO-RD-GR 00718/2026 | B42: ENC-MLGR01 000162/2026 | C42: 712600466 | E42: TROCA DE TRAFO QUEIMADO 5700417087 ETO-RD-GR 718/2026 ZONA RURAL - GOIANORTE 0087_x000D_ _x000D_ TRAFO RETIRADO_x000D_ POTÊNCIA : 05KVA_x000D_ TENSÃO : 19.9KV _x000D_ Nº ENERGISA (CITD) : ILEGIVEL_x000D_ Nº DE SÉRIE : 172224_x000D_ MARCA : VIJAI_x000D_ DATA FABRICAÇÃO : 08/2010_x000D_ IMPEDANCIA : 3.14_x000D_ POS. TAP : 01_x000D_ _x000D_ TRAFO INSTALADO_x000D_ POTÊNCIA : 15KVA_x000D_ TENSÃO : 19.9KV _x000D_ Nº ENERGISA (CITD) : 149509_x000D_ Nº DE SÉRIE : 822944_x000D_ MARCA : TRAEL_x000D_ DATA FABRICAÇÃO : 03/2026_x000D_ IMPEDANCIA : 3.0_x000D_ POS. TAP : 03_x000D_ _x000D_ MEDIÇÃO 1: 00.39_x000D_ MEDIÇÃO 2: 00.20_x000D_ MEDIÇÃO 3: 00.14_x000D_ _x000D_ COORDENADA_x000D_ X: 733055_x000D_ Y: 9015992_x000D_ | F42: QUEIMADO | G42: SOBRECARGA | H42: QUEIMADO | I42: SOBRECARGA | J42: MC - SUBSTITUIÇÃO DE TRANSFORMADOR | K42: 2026 | L42: LD02022033 | M42: 5700417087 | N42: 8812 | O42: EMERGENCIAL | P42: SS ATENDIDA | Q42: 46217.39 | R42: 46217.833 | S42: 46220.39 | T42: BLOCO TRANSFORMADOR DE DISTRIBUIÇÃO | U42: BABACULANDIA | V42: CLEIBER DA SILVA | W42: RURAL | X42: FORMS SUBST DE TRANSFORMADOR | Y42: trafo 5700417087 e para raio queimado acesso livre | Z42: 15 | AA42: 5 | AB42: 15 | AC42: 46225.761
A43: ETO-RD-AR 00872/2026 | B43: ENC-MLAR01 000202/2026 | C43: 612600532 | E43: ETO-RD-AR 872/2026_x000D_ TRAFO 5710241016_x000D_ TRAFO RETIRADO_x000D_ POTÊNCIA : 10 KVA_x000D_ TENSÃO : 34.5 KV_x000D_ Nº ENERGISA (CITD) : ILEGIVEL_x000D_ Nº DE SÉRIE : 66567_x000D_ MARCA : TRAEL_x000D_ DATA FABRICAÇÃO : 10/2005_x000D_ IMPEDANCIA : 3,01_x000D_ POS. TAP : 03_x000D_ _x000D_ TRAFO INSTALADO_x000D_ POTÊNCIA : 15 KVA_x000D_ TENSÃO : 34.5 KV_x000D_ Nº ENERGISA (CITD) : 149646_x000D_ Nº DE SÉRIE : 469632_x000D_ MARCA : TRAEL_x000D_ DATA FABRICAÇÃO : 05/2018_x000D_ IMPEDANCIA : 2,89_x000D_ POS. TAP : 05_x000D_ | F43: QUEIMADO | G43: DESCARGA ATMOSFÉRICA | H43: QUEIMADO | I43: DESCARGA ATMOSFÉRICA | J43: MC - SUBSTITUIÇÃO DE TRANSFORMADOR | K43: 2026 | L43: LD01095030 | M43: 5710241016 | N43: 8812 | O43: EMERGENCIAL | P43: SS ATENDIDA | Q43: 46159.747 | R43: 46160.677 | S43: 46162.747 | T43: BLOCO TRANSFORMADOR DE DISTRIBUIÇÃO | U43: WANDERLANDIA | V43: STANLEY APARECIDO DO CARMO | W43: RURAL | X43: FORMS SUBST DE TRANSFORMADOR | Y43: Trafo 5710241016 Queimado Potencia: 10 KVATensão: 34,5 KVPara raio: Queimado Acesso: livreEquipe: 004op26 (63)99214-9597 | Z43: 15 | AA43: 10 | AB43: 10 KVA | AC43: 46225.761
...

Sheet COLETA
C1: EMPRESA | D1: Coluna1 | E1: REGIONAL | F1: POLO | G1: LOCALIDADE | H1: LOCAL | I1: ALIMENTADOR | J1: NÚMERO OPERATIVO | K1: MATHEUS | L1: Nº DA OCORRÊNCIA | M1: CONCAT | N1: DATA OC | O1: CAUSA | P1: DESC_CAUSA | Q1: SITUAÇÃO | R1: NS RETIRADO | S1: N_TOMBAMENTO_RETIRADO | T1: FABRICANTE | U1: DATA_FABRICAÇÃO | V1: FASES | W1: CLASSE DE TENSÃO | X1: POTÊNCIA RETIRADA | Y1: REFORMADO | Z1: REFORMADORA | AA1: DATA REFORMA | AB1: NS INSTALADO | AC1: N_TOMBAMENTO_INSTALADO | AD1: POTENCIA INSTALADA | AE1: OS (SGM) | AF1: COD. EQUIPE SUBSTITUIÇÃO | AG1: NÚMERO OBRA | AH1: QTDE OCORRÊNCIAS ANTES DA QUEIMA (12M) | AI1: EXISTE GD? | AJ1: CARREGAMENTO % | AK1: Carregamento GD | AL1: Reclamações
A2: =_xlfn.CONCAT(Table1[[#This Row],[NÚMERO OPERATIVO]],TRIM(Table1[[#This Row],[OS (SGM)]])) -> 5700469083DLP-MLPA01 000007/2026 | C2: ETO | D2: 5700469083DLP-MLPA01 000007/2026 | E2: CENTRO | F2: PALMAS | G2: APARECIDA DO RIO NEGRO | H2: RURAL | I2: LD01059122 | J2: 5700469083 | K2: =_xlfn.XLOOKUP(Table1[[#This Row],[NÚMERO OPERATIVO]],#REF!,#REF!) -> #REF! | L2: 20264078451012 | M2: =_xlfn.CONCAT(Table1[[#This Row],[NÚMERO OPERATIVO]],Table1[[#This Row],[DATA OC]]) -> 570046908346034,7742708333 | N2: 46034.774 | O2: QUEIMADO | P2: DESCARGA ATMOSFÉRICA | Q2: QUEIMADO | R2: 177594 | S2: ILGIVEL | T2: VIJAI | U2: 01/09/2010 10:36:50 | V2: 1F | W2: 34.5 | X2: 5 | Y2: NÃO É REFORMADO | Z2: NÃO É REFORMADO | AA2: 17/01/2026 | AB2: 271379 | AC2: 145190 | AD2: 25 | AE2: DLP-MLPA01 000007/2026 | AF2: DOLP-RD-PA | AG2: 112600121 | AH2: 1
A3: =_xlfn.CONCAT(Table1[[#This Row],[NÚMERO OPERATIVO]],Table1[[#This Row],[OS (SGM)]]) -> 5700482083DLP-MLPA01 000013/2026 | C3: ETO | D3: 5700482083DLP-MLPA01 000013/2026 | E3: CENTRO | F3: PALMAS | G3: APARECIDA DO RIO NEGRO | H3: RURAL | I3: LD01059122 | J3: 5700482083 | K3: =_xlfn.XLOOKUP(Table1[[#This Row],[NÚMERO OPERATIVO]],#REF!,#REF!) -> #REF! | L3: 20264085646931 | M3: =_xlfn.CONCAT(Table1[[#This Row],[NÚMERO OPERATIVO]],Table1[[#This Row],[DATA OC]]) -> 570048208346039,7143981481 | N3: 46039.714 | O3: QUEIMADO | P3: NÃO IDENTIFICADO | Q3: QUEIMADO | R3: 236340 | S3: ILEGIVEL | T3: ITB | U3: 01/11/2004 17:18:24 | V3: 1F | W3: 34.5 | X3: 15 | Y3: NÃO É REFORMADO | Z3: NÃO É REFORMADO | AA3: 19/01/2026 | AB3: 435312 | AC3: 126789 | AD3: 15 | AE3: DLP-MLPA01 000013/2026 | AF3: DOLP-RD-PA | AG3: 112600225 | AH3: 1
A4: =_xlfn.CONCAT(Table1[[#This Row],[NÚMERO OPERATIVO]],Table1[[#This Row],[OS (SGM)]]) -> 5727558083DLP-MLPA02 000014/2026 | C4: ETO | D4: 5727558083DLP-MLPA02 000014/2026 | E4: CENTRO | F4: PALMAS | G4: APARECIDA DO RIO NEGRO | H4: RURAL | I4: LD01059122 | J4: 5727558083 | K4: =_xlfn.XLOOKUP(Table1[[#This Row],[NÚMERO OPERATIVO]],#REF!,#REF!) -> #REF! | L4: 20264113074466 | M4: =_xlfn.CONCAT(Table1[[#This Row],[NÚMERO OPERATIVO]],Table1[[#This Row],[DATA OC]]) -> 572755808346053,5055324074 | N4: 46053.506 | O4: QUEIMADO | P4: NÃO IDENTIFICADO | Q4: QUEIMADO | R4: 474656 | S4: 117141 | T4: TRAEL | U4: 01/07/2018 09:08:30 | V4: 1F | W4: 34.5 | X4: 15 | Y4: NÃO É REFORMADO | Z4: NÃO É REFORMADO | AA4: 04/02/2026 | AB4: 290333 | AC4: 149772 | AD4: 15 | AE4: DLP-MLPA02 000014/2026 | AF4: DOLP-RD-PA | AG4: 112600180 | AH4: 1
A5: =_xlfn.CONCAT(Table1[[#This Row],[NÚMERO OPERATIVO]],Table1[[#This Row],[OS (SGM)]]) -> 5700770083DLP-MLPA02 000001/2026 | C5: ETO | D5: 5700770083DLP-MLPA02 000001/2026 | E5: CENTRO | F5: PALMAS | G5: APARECIDA DO RIO NEGRO | H5: RURAL | I5: LD02059122 | J5: 5700770083 | K5: =_xlfn.XLOOKUP(Table1[[#This Row],[NÚMERO OPERATIVO]],#REF!,#REF!) -> #REF! | L5: 20264062932834 | M5: =_xlfn.CONCAT(Table1[[#This Row],[NÚMERO OPERATIVO]],Table1[[#This Row],[DATA OC]]) -> 570077008346026,7250115741 | N5: 46026.725 | O5: QUEIMADO | P5: DESCARGA ATMOSFÉRICA | Q5: QUEIMADO | R5: 1600355 | S5: 141651 | T5: ITB | U5: 01/04/2024 09:43:30 | V5: 1F | W5: 34.5 | X5: 15 | Y5: NÃO É REFORMADO | Z5: CPFL | AA5: 09/01/2026 | AB5: 1014506 | AC5: 134574 | AD5: 15 | AE5: DLP-MLPA02 000001/2026 | AF5: DOLP-RD-PA | AG5: 112600061 | AH5: 1
A6: =_xlfn.CONCAT(Table1[[#This Row],[NÚMERO OPERATIVO]],Table1[[#This Row],[OS (SGM)]]) -> 5700307083DLP-MLPA03 000004/2026 | C6: ETO | D6: 5700307083DLP-MLPA03 000004/2026 | E6: CENTRO | F6: PALMAS | G6: APARECIDA DO RIO NEGRO | H6: RURAL | I6: LD03059122 | J6: 5700307083 | K6: =_xlfn.XLOOKUP(Table1[[#This Row],[NÚMERO OPERATIVO]],#REF!,#REF!) -> #REF! | L6: 20264097382713 | M6: =_xlfn.CONCAT(Table1[[#This Row],[NÚMERO OPERATIVO]],Table1[[#This Row],[DATA OC]]) -> 570030708346047,8396990741 | N6: 46047.84 | O6: QUEIMADO | P6: VAZAMENTO DE ÓLEO | Q6: QUEIMADO | R6: 497936 | S6: 13706 | T6: INCONTRAZA | U6: 01/11/2007 09:39:35 | V6: 1F | W6: 34.5 | X6: 5 | Y6: NÃO É REFORMADO | Z6: NÃO É REFORMADO | AA6: 30/01/2026 | AB6: 1615822 | AC6: 146300 | AD6: 15 | AE6: DLP-MLPA03 000004/2026 | AF6: DOLP-RD-PA | AG6: 112600148 | AH6: 1
A7: =_xlfn.CONCAT(Table1[[#This Row],[NÚMERO OPERATIVO]],Table1[[#This Row],[OS (SGM)]]) -> 5700298253DLP-MLPA01 000038/2026 | C7: ETO | D7: 5700298253DLP-MLPA01 000038/2026 | E7: CENTRO | F7: PALMAS | G7: CHAPADA DE AREIA | H7: RURAL | I7: LD03062013 | J7: 5700298253 | K7: =_xlfn.XLOOKUP(Table1[[#This Row],[NÚMERO OPERATIVO]],#REF!,#REF!) -> #REF! | L7: 20264117076029 | M7: =_xlfn.CONCAT(Table1[[#This Row],[NÚMERO OPERATIVO]],Table1[[#This Row],[DATA OC]]) -> 570029825346057,3625462963 | N7: 46057.363 | O7: QUEIMADO | P7: DESCARGA ATMOSFÉRICA | Q7: QUEIMADO | R7: 128152 | S7: 0 | T7: VIJAI | U7: 01/01/2018 09:18:17 | V7: 1F | W7: 34.5 | X7: 5 | Y7: NÃO É REFORMADO | Z7: NÃO É REFORMADO | AA7: 06/02/2026 | AB7: 1600373 | AC7: 141669 | AD7: 15 | AE7: DLP-MLPA01 000038/2026 | AF7: DOLP-RD-PA | AG7: 112600266 | AH7: 1
A8: =_xlfn.CONCAT(Table1[[#This Row],[NÚMERO OPERATIVO]],Table1[[#This Row],[OS (SGM)]]) -> 5700221196DLP-MLPA01 000054/2026 | C8: ETO | D8: 5700221196DLP-MLPA01 000054/2026 | E8: CENTRO | F8: PALMAS | G8: LAGOA DO TOCANTINS | H8: RURAL | I8: LD02059122 | J8: 5700221196 | K8: =_xlfn.XLOOKUP(Table1[[#This Row],[NÚMERO OPERATIVO]],#REF!,#REF!) -> #REF! | L8: 20264121766011 | M8: =_xlfn.CONCAT(Table1[[#This Row],[NÚMERO OPERATIVO]],Table1[[#This Row],[DATA OC]]) -> 570022119646063,0092708333 | N8: 46063.009 | O8: QUEIMADO | P8: DESCARGA ATMOSFÉRICA | Q8: QUEIMADO | R8: 78606 | S8: 0 | T8: TRAEL | U8: 01/03/2006 10:14:18 | V8: 1F | W8: 34.5 | X8: 10 | Y8: NÃO É REFORMADO | AA8: 23/02/2026 | AB8: 297839 | AC8: 149875 | AD8: 15 | AE8: DLP-MLPA01 000054/2026 | AF8: DOLP-RD-PA | AG8: 112600185 | AH8: 1
A9: =_xlfn.CONCAT(Table1[[#This Row],[NÚMERO OPERATIVO]],Table1[[#This Row],[OS (SGM)]]) -> 5700227196DLP-MLPA01 000002/2026 | C9: ETO | D9: 5700227196DLP-MLPA01 000002/2026 | E9: CENTRO | F9: PALMAS | G9: LAGOA DO TOCANTINS | H9: RURAL | I9: LD02059122 | J9: 5700227196 | K9: =_xlfn.XLOOKUP(Table1[[#This Row],[NÚMERO OPERATIVO]],#REF!,#REF!) -> #REF! | L9: 20264062695982 | M9: =_xlfn.CONCAT(Table1[[#This Row],[NÚMERO OPERATIVO]],Table1[[#This Row],[DATA OC]]) -> 570022719646024,8898958333 | N9: 46024.89 | O9: QUEIMADO | P9: NÃO IDENTIFICADO | Q9: QUEIMADO | R9: 0 | S9: 0 | T9: ABB | U9: 10/02/2026 10:25:09 | V9: 1F | W9: 34.5 | X9: 10 | Y9: CPFL | Z9: CPFL | AA9: 03/02/2026 | AB9: 0 | AC9: 0 | AD9: 15 | AE9: DLP-MLPA01 000002/2026 | AF9: DOLP-RD-PA | AG9: 112600274 | AH9: 1
A10: =_xlfn.CONCAT(Table1[[#This Row],[NÚMERO OPERATIVO]],Table1[[#This Row],[OS (SGM)]]) -> 5700602196DLP-MLPA01 000039/2026 | C10: ETO | D10: 5700602196DLP-MLPA01 000039/2026 | E10: CENTRO | F10: PALMAS | G10: LAGOA DO TOCANTINS | H10: RURAL | I10: LD02059122 | J10: 5700602196 | K10: =_xlfn.XLOOKUP(Table1[[#This Row],[NÚMERO OPERATIVO]],#REF!,#REF!) -> #REF! | L10: 20264117004593 | M10: =_xlfn.CONCAT(Table1[[#This Row],[NÚMERO OPERATIVO]],Table1[[#This Row],[DATA OC]]) -> 570060219646056,7008796296 | N10: 46056.701 | O10: QUEIMADO | P10: NÃO IDENTIFICADO | Q10: QUEIMADO | R10: 202491 | S10: 0 | T10: VIJAI | U10: 01/11/2011 09:51:00 | V10: 1F | W10: 34.5 | X10: 5 | Y10: NÃO É REFORMADO | Z10: CPFL | AB10: 345311 | AC10: 109946 | AD10: 15 | AE10: DLP-MLPA01 000039/2026 | AF10: DOLP-RD-PA | AG10: 112600182 | AH10: 1
A11: =_xlfn.CONCAT(Table1[[#This Row],[NÚMERO OPERATIVO]],Table1[[#This Row],[OS (SGM)]]) -> 5710106196DLP-MLPA02 000009/2026 | C11: ETO | D11: 5710106196DLP-MLPA02 000009/2026 | E11: CENTRO | F11: PALMAS | G11: LAGOA DO TOCANTINS | H11: RURAL | I11: LD02059122 | J11: 5710106196 | K11: =_xlfn.XLOOKUP(Table1[[#This Row],[NÚMERO OPERATIVO]],#REF!,#REF!) -> #REF! | L11: 20264096615371 | M11: =_xlfn.CONCAT(Table1[[#This Row],[NÚMERO OPERATIVO]],Table1[[#This Row],[DATA OC]]) -> 571010619646046,4916666667 | N11: 46046.492 | O11: QUEIMADO | P11: NÃO IDENTIFICADO | Q11: QUEIMADO | R11: 459968 | S11: ILEGÍVEL | T11: ITB | U11: 11/02/2007 16:17:09 | V11: 1F | W11: 34.5 | X11: 5 | Y11: INTEL | Z11: NÃO É REFORMADO | AA11: 11/02/2009 | AB11: C290389 | AC11: 149796 | AD11: 15 | AE11: DLP-MLPA02 000009/2026 | AF11: DOLP-RD-PA | AG11: 112600198 | AH11: 1
A12: =_xlfn.CONCAT(Table1[[#This Row],[NÚMERO OPERATIVO]],Table1[[#This Row],[OS (SGM)]]) -> 5736153196DLP-MLPA03 000011/2026 | C12: ETO | D12: 5736153196DLP-MLPA03 000011/2026 | E12: CENTRO | F12: PALMAS | G12: LAGOA DO TOCANTINS | H12: RURAL | I12: LD02059122 | J12: 5736153196 | K12: =_xlfn.XLOOKUP(Table1[[#This Row],[NÚMERO OPERATIVO]],#REF!,#REF!) -> #REF! | L12: 20264113143399 | M12: =_xlfn.CONCAT(Table1[[#This Row],[NÚMERO OPERATIVO]],Table1[[#This Row],[DATA OC]]) -> 573615319646053,7020717593 | N12: 46053.702 | O12: QUEIMADO | P12: DESCARGA ATMOSFÉRICA | Q12: QUEIMADO | R12: 0 | S12: 0 | T12: ABB | U12: 10/02/2026 10:06:19 | V12: 1F | W12: 13.8 | X12: 10 | Y12: CPFL | Z12: CPFL | AA12: 10/02/2026 | AB12: 0 | AC12: 0 | AD12: 15 | AE12: DLP-MLPA03 000011/2026 | AF12: DOLP-RD-PA | AG12: 112600282 | AH12: 1
A13: =_xlfn.CONCAT(Table1[[#This Row],[NÚMERO OPERATIVO]],Table1[[#This Row],[OS (SGM)]]) -> 5737864196DLP-MLPA01 000056/2026 | C13: ETO | D13: 5737864196DLP-MLPA01 000056/2026 | E13: CENTRO | F13: PALMAS | G13: LAGOA DO TOCANTINS | H13: RURAL | I13: LD02059122 | J13: 5737864196 | K13: =_xlfn.XLOOKUP(Table1[[#This Row],[NÚMERO OPERATIVO]],#REF!,#REF!) -> #REF! | L13: 20264123796101 | M13: =_xlfn.CONCAT(Table1[[#This Row],[NÚMERO OPERATIVO]],Table1[[#This Row],[DATA OC]]) -> 573786419646064,5174189815 | N13: 46064.517 | O13: QUEIMADO | P13: NÃO IDENTIFICADO | Q13: QUEIMADO | R13: 459007 | S13: 112556 | T13: TRAEL | U13: 01/02/2026 18:25:01 | V13: 1F | W13: 34.5 | X13: 15 | Y13: NÃO É REFORMADO | Z13: NÃO É REFORMADO | AA13: 04/03/2026 | AB13: 799471 | AC13: 149122 | AD13: 15 | AE13: DLP-MLPA01 000056/2026 | AF13: DOLP-RD-PA | AG13: 112600260 | AH13: 1
A14: =_xlfn.CONCAT(Table1[[#This Row],[NÚMERO OPERATIVO]],Table1[[#This Row],[OS (SGM)]]) -> 5753804196DLP-MPPA01 000004/2026 | C14: ETO | D14: 5753804196DLP-MPPA01 000004/2026 | E14: CENTRO | F14: PALMAS | G14: LAGOA DO TOCANTINS | H14: RURAL | I14: LD02059122 | J14: 5753804196 | K14: =_xlfn.XLOOKUP(Table1[[#This Row],[NÚMERO OPERATIVO]],#REF!,#REF!) -> #REF! | L14: 20264064897583 | M14: =_xlfn.CONCAT(Table1[[#This Row],[NÚMERO OPERATIVO]],Table1[[#This Row],[DATA OC]]) -> 575380419646026,6832291667 | N14: 46026.683 | O14: QUEIMADO | P14: DESCARGA ATMOSFÉRICA | Q14: QUEIMADO | R14: 692910 | S14: 012811 | T14: TRAEL | U14: 01/08/2024 07:48:54 | V14: 3F | W14: 34.5 | X14: 45 | Y14: NÃO É REFORMADO | Z14: NÃO É REFORMADO | AA14: 09/01/2026 | AB14: 1616966 | AC14: 146094 | AD14: 45 | AE14: DLP-MPPA01 000004/2026 | AF14: DOLP-RD-PA | AG14: 112600057 | AH14: 1
A15: =_xlfn.CONCAT(Table1[[#This Row],[NÚMERO OPERATIVO]],Table1[[#This Row],[OS (SGM)]]) -> 5700628010DLP-MLPA01 000060/2026 | C15: ETO | D15: 5700628010DLP-MLPA01 000060/2026 | E15: CENTRO | F15: PALMAS | G15: LAJEADO | H15: RURAL | I15: LD03059122 | J15: 5700628010 | K15: =_xlfn.XLOOKUP(Table1[[#This Row],[NÚMERO OPERATIVO]],#REF!,#REF!) -> #REF! | L15: será aberta em campo | M15: =_xlfn.CONCAT(Table1[[#This Row],[NÚMERO OPERATIVO]],Table1[[#This Row],[DATA OC]]) -> 570062801046065,8999652778 | N15: 46065.9 | O15: QUEIMADO | P15: NÃO IDENTIFICADO | Q15: QUEIMADO | V15: 1F | W15: 34.5 | X15: 15 | AD15: 15 | AE15: DLP-MLPA01 000060/2026 | AF15: DOLP-RD-PA | AG15: 112600272 | AH15: 1
A16: =_xlfn.CONCAT(Table1[[#This Row],[NÚMERO OPERATIVO]],Table1[[#This Row],[OS (SGM)]]) -> 5700671010DLP-MLPA01 000001/2026 | C16: ETO | D16: 5700671010DLP-MLPA01 000001/2026 | E16: CENTRO | F16: PALMAS | G16: LAJEADO | H16: RURAL | I16: LD03059122 | J16: 5700671010 | K16: =_xlfn.XLOOKUP(Table1[[#This Row],[NÚMERO OPERATIVO]],#REF!,#REF!) -> #REF! | L16: 20264060599303 | M16: =_xlfn.CONCAT(Table1[[#This Row],[NÚMERO OPERATIVO]],Table1[[#This Row],[DATA OC]]) -> 570067101046023,5344907407 | N16: 46023.534 | O16: QUEIMADO | P16: DESCARGA ATMOSFÉRICA | Q16: QUEIMADO | R16: 533284 | S16: 123494 | T16: TRAEL | U16: 01/03/2020 09:03:39 | V16: 1F | W16: 34.5 | X16: 150 | Y16: NÃO É REFORMADO | Z16: CPFL | AA16: 12/01/2026 | AB16: 474621 | AC16: 117106 | AD16: 15 | AE16: DLP-MLPA01 000001/2026 | AF16: DOLP-RD-PA | AG16: 112600085 | AH16: 1
